Workbook

Sheet effect_quant_by_period
A1: id | B1: time | C1: policy details | D1: policy effects and effect duration | E1: policy_group_name | F1: cumulative_policy_effect_mw | G1: observed cumulative MW deployed | H1: estimated cumulative MW deployed | I1: error-adjusted total policy effect in MW | J1: error-adjusted non-policy & unidentified policy effect in MW | K1: cumulative error-adjusted total policy mix effect in MW
A2: AUT | B2: 2001 | D2: - | E2: {=_xlfn.IFS(D2=policy_name_clustering!$A$2,policy_name_clustering!$C$2,D2=policy_name_clustering!$A$3,policy_name_clustering!$C$3,D2=policy_name_clustering!$A$4,policy_name_clustering!$C$4,D2=policy_name_clustering!$A$5,policy_name_clustering!$C$5,D2=policy_name_clustering!$A$6,policy_name_clustering!$C$6,D2=policy_name_clustering!$A$7,policy_name_clustering!$C$7,D2=policy_name_clustering!$A$8,policy_name_clustering!$C$8,D2=policy_name_clustering!$A$9,policy_name_clustering!$C$9,D2=policy_name_clustering!$A$10,policy_name_clustering!$C$10,D2=policy_name_clustering!$A$11,policy_name_clustering!$C$11,D2=policy_name_clustering!$A$12,policy_name_clustering!$C$12,D2="-","")} | G2: =solar_cum_cap!C3 -> 7 | H2: =estimated_capacity!C2 -> 37.662573 | I2: {=_xlfn.IFS(D2= ""," ",D2<> " ",F2*(G2/H2))} -> 0 | J2: {=_xlfn.IFS(D2= ""," ",D2<> " ",(H2-F2)*(G2/H2))} -> 7 | K2: {=IF(ISNUMBER(H2),_xlfn.IFS(D2= ""," ",D2<> " ",F2*(G2/H2)),"")} -> 0
A3: AUT | B3: 2002 | D3: - | E3: {=_xlfn.IFS(D3=policy_name_clustering!$A$2,policy_name_clustering!$C$2,D3=policy_name_clustering!$A$3,policy_name_clustering!$C$3,D3=policy_name_clustering!$A$4,policy_name_clustering!$C$4,D3=policy_name_clustering!$A$5,policy_name_clustering!$C$5,D3=policy_name_clustering!$A$6,policy_name_clustering!$C$6,D3=policy_name_clustering!$A$7,policy_name_clustering!$C$7,D3=policy_name_clustering!$A$8,policy_name_clustering!$C$8,D3=policy_name_clustering!$A$9,policy_name_clustering!$C$9,D3=policy_name_clustering!$A$10,policy_name_clustering!$C$10,D3=policy_name_clustering!$A$11,policy_name_clustering!$C$11,D3=policy_name_clustering!$A$12,policy_name_clustering!$C$12,D3="-","")} | G3: =solar_cum_cap!C4 -> 9 | H3: =estimated_capacity!C3 -> 67.605946 | I3: {=_xlfn.IFS(D3= ""," ",D3<> " ",F3*(G3/H3))} -> 0 | J3: {=_xlfn.IFS(D3= ""," ",D3<> " ",(H3-F3)*(G3/H3))} -> 9 | K3: {=IF(ISNUMBER(H3),_xlfn.IFS(D3= ""," ",D3<> " ",F3*(G3/H3)),"")} -> 0
A4: AUT | B4: 2003 | D4: - | E4: {=_xlfn.IFS(D4=policy_name_clustering!$A$2,policy_name_clustering!$C$2,D4=policy_name_clustering!$A$3,policy_name_clustering!$C$3,D4=policy_name_clustering!$A$4,policy_name_clustering!$C$4,D4=policy_name_clustering!$A$5,policy_name_clustering!$C$5,D4=policy_name_clustering!$A$6,policy_name_clustering!$C$6,D4=policy_name_clustering!$A$7,policy_name_clustering!$C$7,D4=policy_name_clustering!$A$8,policy_name_clustering!$C$8,D4=policy_name_clustering!$A$9,policy_name_clustering!$C$9,D4=policy_name_clustering!$A$10,policy_name_clustering!$C$10,D4=policy_name_clustering!$A$11,policy_name_clustering!$C$11,D4=policy_name_clustering!$A$12,policy_name_clustering!$C$12,D4="-","")} | G4: =solar_cum_cap!C5 -> 23 | H4: =estimated_capacity!C4 -> 111.45853 | I4: {=_xlfn.IFS(D4= ""," ",D4<> " ",F4*(G4/H4))} -> 0 | J4: {=_xlfn.IFS(D4= ""," ",D4<> " ",(H4-F4)*(G4/H4))} -> 23 | K4: {=IF(ISNUMBER(H4),_xlfn.IFS(D4= ""," ",D4<> " ",F4*(G4/H4)),"")} -> 0
A5: AUT | B5: 2004 | D5: - | E5: {=_xlfn.IFS(D5=policy_name_clustering!$A$2,policy_name_clustering!$C$2,D5=policy_name_clustering!$A$3,policy_name_clustering!$C$3,D5=policy_name_clustering!$A$4,policy_name_clustering!$C$4,D5=policy_name_clustering!$A$5,policy_name_clustering!$C$5,D5=policy_name_clustering!$A$6,policy_name_clustering!$C$6,D5=policy_name_clustering!$A$7,policy_name_clustering!$C$7,D5=policy_name_clustering!$A$8,policy_name_clustering!$C$8,D5=policy_name_clustering!$A$9,policy_name_clustering!$C$9,D5=policy_name_clustering!$A$10,policy_name_clustering!$C$10,D5=policy_name_clustering!$A$11,policy_name_clustering!$C$11,D5=policy_name_clustering!$A$12,policy_name_clustering!$C$12,D5="-","")} | G5: =solar_cum_cap!C6 -> 27 | H5: =estimated_capacity!C5 -> 179.5902 | I5: {=_xlfn.IFS(D5= ""," ",D5<> " ",F5*(G5/H5))} -> 0 | J5: {=_xlfn.IFS(D5= ""," ",D5<> " ",(H5-F5)*(G5/H5))} -> 27 | K5: {=IF(ISNUMBER(H5),_xlfn.IFS(D5= ""," ",D5<> " ",F5*(G5/H5)),"")} -> 0
A6: AUT | B6: 2005 | D6: - | E6: {=_xlfn.IFS(D6=policy_name_clustering!$A$2,policy_name_clustering!$C$2,D6=policy_name_clustering!$A$3,policy_name_clustering!$C$3,D6=policy_name_clustering!$A$4,policy_name_clustering!$C$4,D6=policy_name_clustering!$A$5,policy_name_clustering!$C$5,D6=policy_name_clustering!$A$6,policy_name_clustering!$C$6,D6=policy_name_clustering!$A$7,policy_name_clustering!$C$7,D6=policy_name_clustering!$A$8,policy_name_clustering!$C$8,D6=policy_name_clustering!$A$9,policy_name_clustering!$C$9,D6=policy_name_clustering!$A$10,policy_name_clustering!$C$10,D6=policy_name_clustering!$A$11,policy_name_clustering!$C$11,D6=policy_name_clustering!$A$12,policy_name_clustering!$C$12,D6="-","")} | G6: =solar_cum_cap!C7 -> 21.018 | H6: =estimated_capacity!C6 -> 248.19562 | I6: {=_xlfn.IFS(D6= ""," ",D6<> " ",F6*(G6/H6))} -> 0 | J6: {=_xlfn.IFS(D6= ""," ",D6<> " ",(H6-F6)*(G6/H6))} -> 21.018 | K6: {=IF(ISNUMBER(H6),_xlfn.IFS(D6= ""," ",D6<> " ",F6*(G6/H6)),"")} -> 0
A7: AUT | B7: 2006 | D7: - | E7: {=_xlfn.IFS(D7=policy_name_clustering!$A$2,policy_name_clustering!$C$2,D7=policy_name_clustering!$A$3,policy_name_clustering!$C$3,D7=policy_name_clustering!$A$4,policy_name_clustering!$C$4,D7=policy_name_clustering!$A$5,policy_name_clustering!$C$5,D7=policy_name_clustering!$A$6,policy_name_clustering!$C$6,D7=policy_name_clustering!$A$7,policy_name_clustering!$C$7,D7=policy_name_clustering!$A$8,policy_name_clustering!$C$8,D7=policy_name_clustering!$A$9,policy_name_clustering!$C$9,D7=policy_name_clustering!$A$10,policy_name_clustering!$C$10,D7=policy_name_clustering!$A$11,policy_name_clustering!$C$11,D7=policy_name_clustering!$A$12,policy_name_clustering!$C$12,D7="-","")} | G7: =solar_cum_cap!C8 -> 22.387 | H7: =estimated_capacity!C7 -> 322.68046 | I7: {=_xlfn.IFS(D7= ""," ",D7<> " ",F7*(G7/H7))} -> 0 | J7: {=_xlfn.IFS(D7= ""," ",D7<> " ",(H7-F7)*(G7/H7))} -> 22.387 | K7: {=IF(ISNUMBER(H7),_xlfn.IFS(D7= ""," ",D7<> " ",F7*(G7/H7)),"")} -> 0
A8: AUT | B8: 2007 | D8: - | E8: {=_xlfn.IFS(D8=policy_name_clustering!$A$2,policy_name_clustering!$C$2,D8=policy_name_clustering!$A$3,policy_name_clustering!$C$3,D8=policy_name_clustering!$A$4,policy_name_clustering!$C$4,D8=policy_name_clustering!$A$5,policy_name_clustering!$C$5,D8=policy_name_clustering!$A$6,policy_name_clustering!$C$6,D8=policy_name_clustering!$A$7,policy_name_clustering!$C$7,D8=policy_name_clustering!$A$8,policy_name_clustering!$C$8,D8=policy_name_clustering!$A$9,policy_name_clustering!$C$9,D8=policy_name_clustering!$A$10,policy_name_clustering!$C$10,D8=policy_name_clustering!$A$11,policy_name_clustering!$C$11,D8=policy_name_clustering!$A$12,policy_name_clustering!$C$12,D8="-","")} | G8: =solar_cum_cap!C9 -> 24.238 | H8: =estimated_capacity!C8 -> 402.12565 | I8: {=_xlfn.IFS(D8= ""," ",D8<> " ",F8*(G8/H8))} -> 0 | J8: {=_xlfn.IFS(D8= ""," ",D8<> " ",(H8-F8)*(G8/H8))} -> 24.238 | K8: {=IF(ISNUMBER(H8),_xlfn.IFS(D8= ""," ",D8<> " ",F8*(G8/H8)),"")} -> 0
A9: AUT | B9: 2008 | D9: - | E9: {=_xlfn.IFS(D9=policy_name_clustering!$A$2,policy_name_clustering!$C$2,D9=policy_name_clustering!$A$3,policy_name_clustering!$C$3,D9=policy_name_clustering!$A$4,policy_name_clustering!$C$4,D9=policy_name_clustering!$A$5,policy_name_clustering!$C$5,D9=policy_name_clustering!$A$6,policy_name_clustering!$C$6,D9=policy_name_clustering!$A$7,policy_name_clustering!$C$7,D9=policy_name_clustering!$A$8,policy_name_clustering!$C$8,D9=policy_name_clustering!$A$9,policy_name_clustering!$C$9,D9=policy_name_clustering!$A$10,policy_name_clustering!$C$10,D9=policy_name_clustering!$A$11,policy_name_clustering!$C$11,D9=policy_name_clustering!$A$12,policy_name_clustering!$C$12,D9="-","")} | G9: =solar_cum_cap!C10 -> 30.12 | H9: =estimated_capacity!C9 -> 499.52628 | I9: {=_xlfn.IFS(D9= ""," ",D9<> " ",F9*(G9/H9))} -> 0 | J9: {=_xlfn.IFS(D9= ""," ",D9<> " ",(H9-F9)*(G9/H9))} -> 30.12 | K9: {=IF(ISNUMBER(H9),_xlfn.IFS(D9= ""," ",D9<> " ",F9*(G9/H9)),"")} -> 0
A10: AUT | B10: 2009 | D10: - | E10: {=_xlfn.IFS(D10=policy_name_clustering!$A$2,policy_name_clustering!$C$2,D10=policy_name_clustering!$A$3,policy_name_clustering!$C$3,D10=policy_name_clustering!$A$4,policy_name_clustering!$C$4,D10=policy_name_clustering!$A$5,policy_name_clustering!$C$5,D10=policy_name_clustering!$A$6,policy_name_clustering!$C$6,D10=policy_name_clustering!$A$7,policy_name_clustering!$C$7,D10=policy_name_clustering!$A$8,policy_name_clustering!$C$8,D10=policy_name_clustering!$A$9,policy_name_clustering!$C$9,D10=policy_name_clustering!$A$10,policy_name_clustering!$C$10,D10=policy_name_clustering!$A$11,policy_name_clustering!$C$11,D10=policy_name_clustering!$A$12,policy_name_clustering!$C$12,D10="-","")} | G10: =solar_cum_cap!C11 -> 48.915 | H10: =estimated_capacity!C10 -> 601.77341 | I10: {=_xlfn.IFS(D10= ""," ",D10<> " ",F10*(G10/H10))} -> 0 | J10: {=_xlfn.IFS(D10= ""," ",D10<> " ",(H10-F10)*(G10/H10))} -> 48.915 | K10: {=IF(ISNUMBER(H10),_xlfn.IFS(D10= ""," ",D10<> " ",F10*(G10/H10)),"")} -> 0
A11: AUT | B11: 2010 | D11: - | E11: {=_xlfn.IFS(D11=policy_name_clustering!$A$2,policy_name_clustering!$C$2,D11=policy_name_clustering!$A$3,policy_name_clustering!$C$3,D11=policy_name_clustering!$A$4,policy_name_clustering!$C$4,D11=policy_name_clustering!$A$5,policy_name_clustering!$C$5,D11=policy_name_clustering!$A$6,policy_name_clustering!$C$6,D11=policy_name_clustering!$A$7,policy_name_clustering!$C$7,D11=policy_name_clustering!$A$8,policy_name_clustering!$C$8,D11=policy_name_clustering!$A$9,policy_name_clustering!$C$9,D11=policy_name_clustering!$A$10,policy_name_clustering!$C$10,D11=policy_name_clustering!$A$11,policy_name_clustering!$C$11,D11=policy_name_clustering!$A$12,policy_name_clustering!$C$12,D11="-","")} | G11: =solar_cum_cap!C12 -> 88.813 | H11: =estimated_capacity!C11 -> 745.20818 | I11: {=_xlfn.IFS(D11= ""," ",D11<> " ",F11*(G11/H11))} -> 0 | J11: {=_xlfn.IFS(D11= ""," ",D11<> " ",(H11-F11)*(G11/H11))} -> 88.813 | K11: {=IF(ISNUMBER(H11),_xlfn.IFS(D11= ""," ",D11<> " ",F11*(G11/H11)),"")} -> 0
A12: AUT | B12: 2011 | D12: - | E12: {=_xlfn.IFS(D12=policy_name_clustering!$A$2,policy_name_clustering!$C$2,D12=policy_name_clustering!$A$3,policy_name_clustering!$C$3,D12=policy_name_clustering!$A$4,policy_name_clustering!$C$4,D12=policy_name_clustering!$A$5,policy_name_clustering!$C$5,D12=policy_name_clustering!$A$6,policy_name_clustering!$C$6,D12=policy_name_clustering!$A$7,policy_name_clustering!$C$7,D12=policy_name_clustering!$A$8,policy_name_clustering!$C$8,D12=policy_name_clustering!$A$9,policy_name_clustering!$C$9,D12=policy_name_clustering!$A$10,policy_name_clustering!$C$10,D12=policy_name_clustering!$A$11,policy_name_clustering!$C$11,D12=policy_name_clustering!$A$12,policy_name_clustering!$C$12,D12="-","")} | G12: =solar_cum_cap!C13 -> 174.07 | H12: =estimated_capacity!C12 -> 942.06133 | I12: {=_xlfn.IFS(D12= ""," ",D12<> " ",F12*(G12/H12))} -> 0 | J12: {=_xlfn.IFS(D12= ""," ",D12<> " ",(H12-F12)*(G12/H12))} -> 174.07 | K12: {=IF(ISNUMBER(H12),_xlfn.IFS(D12= ""," ",D12<> " ",F12*(G12/H12)),"")} -> 0
A13: AUT | B13: 2012 | D13: - | E13: {=_xlfn.IFS(D13=policy_name_clustering!$A$2,policy_name_clustering!$C$2,D13=policy_name_clustering!$A$3,policy_name_clustering!$C$3,D13=policy_name_clustering!$A$4,policy_name_clustering!$C$4,D13=policy_name_clustering!$A$5,policy_name_clustering!$C$5,D13=policy_name_clustering!$A$6,policy_name_clustering!$C$6,D13=policy_name_clustering!$A$7,policy_name_clustering!$C$7,D13=policy_name_clustering!$A$8,policy_name_clustering!$C$8,D13=policy_name_clustering!$A$9,policy_name_clustering!$C$9,D13=policy_name_clustering!$A$10,policy_name_clustering!$C$10,D13=policy_name_clustering!$A$11,policy_name_clustering!$C$11,D13=policy_name_clustering!$A$12,policy_name_clustering!$C$12,D13="-","")} | G13: =solar_cum_cap!C14 -> 337.483 | H13: =estimated_capacity!C13 -> 1181.3722 | I13: {=_xlfn.IFS(D13= ""," ",D13<> " ",F13*(G13/H13))} -> 0 | J13: {=_xlfn.IFS(D13= ""," ",D13<> " ",(H13-F13)*(G13/H13))} -> 337.483 | K13: {=IF(ISNUMBER(H13),_xlfn.IFS(D13= ""," ",D13<> " ",F13*(G13/H13)),"")} -> 0
... A24: AUT | B24: 2023 | D24: - | E24: {=_xlfn.IFS(D24=policy_name_clustering!$A$2,policy_name_clustering!$C$2,D24=policy_name_clustering!$A$3,policy_name_clustering!$C$3,D24=policy_name_clustering!$A$4,policy_name_clustering!$C$4,D24=policy_name_clustering!$A$5,policy_name_clustering!$C$5,D24=policy_name_clustering!$A$6,policy_name_clustering!$C$6,D24=policy_name_clustering!$A$7,policy_name_clustering!$C$7,D24=policy_name_clustering!$A$8,policy_name_clustering!$C$8,D24=policy_name_clustering!$A$9,policy_name_clustering!$C$9,D24=policy_name_clustering!$A$10,policy_name_clustering!$C$10,D24=policy_name_clustering!$A$11,policy_name_clustering!$C$11,D24=policy_name_clustering!$A$12,policy_name_clustering!$C$12,D24="-","")} | G24: =solar_cum_cap!C25 -> 6394.811 | H24: =estimated_capacity!C24 -> 4802.3446 | I24: {=_xlfn.IFS(D24= ""," ",D24<> " ",F24*(G24/H24))} -> 0 | J24: {=_xlfn.IFS(D24= ""," ",D24<> " ",(H24-F24)*(G24/H24))} -> 6394.811 | K24: {=IF(ISNUMBER(H24),_xlfn.IFS(D24= ""," ",D24<> " ",F24*(G24/H24)),"")} -> 0
A25: BEL | B25: 2001 | D25: - | E25: {=_xlfn.IFS(D25=policy_name_clustering!$A$2,policy_name_clustering!$C$2,D25=policy_name_clustering!$A$3,policy_name_clustering!$C$3,D25=policy_name_clustering!$A$4,policy_name_clustering!$C$4,D25=policy_name_clustering!$A$5,policy_name_clustering!$C$5,D25=policy_name_clustering!$A$6,policy_name_clustering!$C$6,D25=policy_name_clustering!$A$7,policy_name_clustering!$C$7,D25=policy_name_clustering!$A$8,policy_name_clustering!$C$8,D25=policy_name_clustering!$A$9,policy_name_clustering!$C$9,D25=policy_name_clustering!$A$10,policy_name_clustering!$C$10,D25=policy_name_clustering!$A$11,policy_name_clustering!$C$11,D25=policy_name_clustering!$A$12,policy_name_clustering!$C$12,D25="-","")} | G25: =solar_cum_cap!C27 -> 0 | H25: =estimated_capacity!C25 -> 100.10894 | I25: {=_xlfn.IFS(D25= ""," ",D25<> " ",F25*(G25/H25))} -> 0 | J25: {=_xlfn.IFS(D25= ""," ",D25<> " ",(H25-F25)*(G25/H25))} -> 0 | K25: {=IF(ISNUMBER(H25),_xlfn.IFS(D25= ""," ",D25<> " ",F25*(G25/H25)),"")} -> 0
A26: BEL | B26: 2002 | D26: - | E26: {=_xlfn.IFS(D26=policy_name_clustering!$A$2,policy_name_clustering!$C$2,D26=policy_name_clustering!$A$3,policy_name_clustering!$C$3,D26=policy_name_clustering!$A$4,policy_name_clustering!$C$4,D26=policy_name_clustering!$A$5,policy_name_clustering!$C$5,D26=policy_name_clustering!$A$6,policy_name_clustering!$C$6,D26=policy_name_clustering!$A$7,policy_name_clustering!$C$7,D26=policy_name_clustering!$A$8,policy_name_clustering!$C$8,D26=policy_name_clustering!$A$9,policy_name_clustering!$C$9,D26=policy_name_clustering!$A$10,policy_name_clustering!$C$10,D26=policy_name_clustering!$A$11,policy_name_clustering!$C$11,D26=policy_name_clustering!$A$12,policy_name_clustering!$C$12,D26="-","")} | G26: =solar_cum_cap!C28 -> 0 | H26: =estimated_capacity!C26 -> 191.18881 | I26: {=_xlfn.IFS(D26= ""," ",D26<> " ",F26*(G26/H26))} -> 0 | J26: {=_xlfn.IFS(D26= ""," ",D26<> " ",(H26-F26)*(G26/H26))} -> 0 | K26: {=IF(ISNUMBER(H26),_xlfn.IFS(D26= ""," ",D26<> " ",F26*(G26/H26)),"")} -> 0
A27: BEL | B27: 2003 | D27: - | E27: {=_xlfn.IFS(D27=policy_name_clustering!$A$2,policy_name_clustering!$C$2,D27=policy_name_clustering!$A$3,policy_name_clustering!$C$3,D27=policy_name_clustering!$A$4,policy_name_clustering!$C$4,D27=policy_name_clustering!$A$5,policy_name_clustering!$C$5,D27=policy_name_clustering!$A$6,policy_name_clustering!$C$6,D27=policy_name_clustering!$A$7,policy_name_clustering!$C$7,D27=policy_name_clustering!$A$8,policy_name_clustering!$C$8,D27=policy_name_clustering!$A$9,policy_name_clustering!$C$9,D27=policy_name_clustering!$A$10,policy_name_clustering!$C$10,D27=policy_name_clustering!$A$11,policy_name_clustering!$C$11,D27=policy_name_clustering!$A$12,policy_name_clustering!$C$12,D27="-","")} | G27: =solar_cum_cap!C29 -> 0 | H27: =estimated_capacity!C27 -> 301.26271 | I27: {=_xlfn.IFS(D27= ""," ",D27<> " ",F27*(G27/H27))} -> 0 | J27: {=_xlfn.IFS(D27= ""," ",D27<> " ",(H27-F27)*(G27/H27))} -> 0 | K27: {=IF(ISNUMBER(H27),_xlfn.IFS(D27= ""," ",D27<> " ",F27*(G27/H27)),"")} -> 0
A28: BEL | B28: 2004 | D28: - | E28: {=_xlfn.IFS(D28=policy_name_clustering!$A$2,policy_name_clustering!$C$2,D28=policy_name_clustering!$A$3,policy_name_clustering!$C$3,D28=policy_name_clustering!$A$4,policy_name_clustering!$C$4,D28=policy_name_clustering!$A$5,policy_name_clustering!$C$5,D28=policy_name_clustering!$A$6,policy_name_clustering!$C$6,D28=policy_name_clustering!$A$7,policy_name_clustering!$C$7,D28=policy_name_clustering!$A$8,policy_name_clustering!$C$8,D28=policy_name_clustering!$A$9,policy_name_clustering!$C$9,D28=policy_name_clustering!$A$10,policy_name_clustering!$C$10,D28=policy_name_clustering!$A$11,policy_name_clustering!$C$11,D28=policy_name_clustering!$A$12,policy_name_clustering!$C$12,D28="-","")} | G28: =solar_cum_cap!C30 -> 0 | H28: =estimated_capacity!C28 -> 440.65569 | I28: {=_xlfn.IFS(D28= ""," ",D28<> " ",F28*(G28/H28))} -> 0 | J28: {=_xlfn.IFS(D28= ""," ",D28<> " ",(H28-F28)*(G28/H28))} -> 0 | K28: {=IF(ISNUMBER(H28),_xlfn.IFS(D28= ""," ",D28<> " ",F28*(G28/H28)),"")} -> 0
A29: BEL | B29: 2005 | D29: - | E29: {=_xlfn.IFS(D29=policy_name_clustering!$A$2,policy_name_clustering!$C$2,D29=policy_name_clustering!$A$3,policy_name_clustering!$C$3,D29=policy_name_clustering!$A$4,policy_name_clustering!$C$4,D29=policy_name_clustering!$A$5,policy_name_clustering!$C$5,D29=policy_name_clustering!$A$6,policy_name_clustering!$C$6,D29=policy_name_clustering!$A$7,policy_name_clustering!$C$7,D29=policy_name_clustering!$A$8,policy_name_clustering!$C$8,D29=policy_name_clustering!$A$9,policy_name_clustering!$C$9,D29=policy_name_clustering!$A$10,policy_name_clustering!$C$10,D29=policy_name_clustering!$A$11,policy_name_clustering!$C$11,D29=policy_name_clustering!$A$12,policy_name_clustering!$C$12,D29="-","")} | G29: =solar_cum_cap!C31 -> 0 | H29: =estimated_capacity!C29 -> 578.00966 | I29: {=_xlfn.IFS(D29= ""," ",D29<> " ",F29*(G29/H29))} -> 0 | J29: {=_xlfn.IFS(D29= ""," ",D29<> " ",(H29-F29)*(G29/H29))} -> 0 | K29: {=IF(ISNUMBER(H29),_xlfn.IFS(D29= ""," ",D29<> " ",F29*(G29/H29)),"")} -> 0
A30: BEL | B30: 2006 | D30: - | E30: {=_xlfn.IFS(D30=policy_name_clustering!$A$2,policy_name_clustering!$C$2,D30=policy_name_clustering!$A$3,policy_name_clustering!$C$3,D30=policy_name_clustering!$A$4,policy_name_clustering!$C$4,D30=policy_name_clustering!$A$5,policy_name_clustering!$C$5,D30=policy_name_clustering!$A$6,policy_name_clustering!$C$6,D30=policy_name_clustering!$A$7,policy_name_clustering!$C$7,D30=policy_name_clustering!$A$8,policy_name_clustering!$C$8,D30=policy_name_clustering!$A$9,policy_name_clustering!$C$9,D30=policy_name_clustering!$A$10,policy_name_clustering!$C$10,D30=policy_name_clustering!$A$11,policy_name_clustering!$C$11,D30=policy_name_clustering!$A$12,policy_name_clustering!$C$12,D30="-","")} | G30: =solar_cum_cap!C32 -> 0 | H30: =estimated_capacity!C30 -> 721.68252 | I30: {=_xlfn.IFS(D30= ""," ",D30<> " ",F30*(G30/H30))} -> 0 | J30: {=_xlfn.IFS(D30= ""," ",D30<> " ",(H30-F30)*(G30/H30))} -> 0 | K30: {=IF(ISNUMBER(H30),_xlfn.IFS(D30= ""," ",D30<> " ",F30*(G30/H30)),"")} -> 0
A31: BEL | B31: 2007 | D31: - | E31: {=_xlfn.IFS(D31=policy_name_clustering!$A$2,policy_name_clustering!$C$2,D31=policy_name_clustering!$A$3,policy_name_clustering!$C$3,D31=policy_name_clustering!$A$4,policy_name_clustering!$C$4,D31=policy_name_clustering!$A$5,policy_name_clustering!$C$5,D31=policy_name_clustering!$A$6,policy_name_clustering!$C$6,D31=policy_name_clustering!$A$7,policy_name_clustering!$C$7,D31=policy_name_clustering!$A$8,policy_name_clustering!$C$8,D31=policy_name_clustering!$A$9,policy_name_clustering!$C$9,D31=policy_name_clustering!$A$10,policy_name_clustering!$C$10,D31=policy_name_clustering!$A$11,policy_name_clustering!$C$11,D31=policy_name_clustering!$A$12,policy_name_clustering!$C$12,D31="-","")} | G31: =solar_cum_cap!C33 -> 0 | H31: =estimated_capacity!C31 -> 870.92112 | I31: {=_xlfn.IFS(D31= ""," ",D31<> " ",F31*(G31/H31))} -> 0 | J31: {=_xlfn.IFS(D31= ""," ",D31<> " ",(H31-F31)*(G31/H31))} -> 0 | K31: {=IF(ISNUMBER(H31),_xlfn.IFS(D31= ""," ",D31<> " ",F31*(G31/H31)),"")} -> 0
A32: BEL | B32: 2008 | D32: - | E32: {=_xlfn.IFS(D32=policy_name_clustering!$A$2,policy_name_clustering!$C$2,D32=policy_name_clustering!$A$3,policy_name_clustering!$C$3,D32=policy_name_clustering!$A$4,policy_name_clustering!$C$4,D32=policy_name_clustering!$A$5,policy_name_clustering!$C$5,D32=policy_name_clustering!$A$6,policy_name_clustering!$C$6,D32=policy_name_clustering!$A$7,policy_name_clustering!$C$7,D32=policy_name_clustering!$A$8,policy_name_clustering!$C$8,D32=policy_name_clustering!$A$9,policy_name_clustering!$C$9,D32=policy_name_clustering!$A$10,policy_name_clustering!$C$10,D32=policy_name_clustering!$A$11,policy_name_clustering!$C$11,D32=policy_name_clustering!$A$12,policy_name_clustering!$C$12,D32="-","")} | G32: =solar_cum_cap!C34 -> 0 | H32: =estimated_capacity!C32 -> 1040.3624 | I32: {=_xlfn.IFS(D32= ""," ",D32<> " ",F32*(G32/H32))} -> 0 | J32: {=_xlfn.IFS(D32= ""," ",D32<> " ",(H32-F32)*(G32/H32))} -> 0 | K32: {=IF(ISNUMBER(H32),_xlfn.IFS(D32= ""," ",D32<> " ",F32*(G32/H32)),"")} -> 0
A33: BEL | B33: 2009 | D33: - | E33: {=_xlfn.IFS(D33=policy_name_clustering!$A$2,policy_name_clustering!$C$2,D33=policy_name_clustering!$A$3,policy_name_clustering!$C$3,D33=policy_name_clustering!$A$4,policy_name_clustering!$C$4,D33=policy_name_clustering!$A$5,policy_name_clustering!$C$5,D33=policy_name_clustering!$A$6,policy_name_clustering!$C$6,D33=policy_name_clustering!$A$7,policy_name_clustering!$C$7,D33=policy_name_clustering!$A$8,policy_name_clustering!$C$8,D33=policy_name_clustering!$A$9,policy_name_clustering!$C$9,D33=policy_name_clustering!$A$10,policy_name_clustering!$C$10,D33=policy_name_clustering!$A$11,policy_name_clustering!$C$11,D33=policy_name_clustering!$A$12,policy_name_clustering!$C$12,D33="-","")} | G33: =solar_cum_cap!C35 -> 386 | H33: =estimated_capacity!C33 -> 1216.2788 | I33: {=_xlfn.IFS(D33= ""," ",D33<> " ",F33*(G33/H33))} -> 0 | J33: {=_xlfn.IFS(D33= ""," ",D33<> " ",(H33-F33)*(G33/H33))} -> 386 | K33: {=IF(ISNUMBER(H33),_xlfn.IFS(D33= ""," ",D33<> " ",F33*(G33/H33)),"")} -> 0
A34: BEL | B34: 2010 | D34: - | E34: {=_xlfn.IFS(D34=policy_name_clustering!$A$2,policy_name_clustering!$C$2,D34=policy_name_clustering!$A$3,policy_name_clustering!$C$3,D34=policy_name_clustering!$A$4,policy_name_clustering!$C$4,D34=policy_name_clustering!$A$5,policy_name_clustering!$C$5,D34=policy_name_clustering!$A$6,policy_name_clustering!$C$6,D34=policy_name_clustering!$A$7,policy_name_clustering!$C$7,D34=policy_name_clustering!$A$8,policy_name_clustering!$C$8,D34=policy_name_clustering!$A$9,policy_name_clustering!$C$9,D34=policy_name_clustering!$A$10,policy_name_clustering!$C$10,D34=policy_name_clustering!$A$11,policy_name_clustering!$C$11,D34=policy_name_clustering!$A$12,policy_name_clustering!$C$12,D34="-","")} | G34: =solar_cum_cap!C36 -> 840.2 | H34: =estimated_capacity!C34 -> 1452.2801 | I34: {=_xlfn.IFS(D34= ""," ",D34<> " ",F34*(G34/H34))} -> 0 | J34: {=_xlfn.IFS(D34= ""," ",D34<> " ",(H34-F34)*(G34/H34))} -> 840.2 | K34: {=IF(ISNUMBER(H34),_xlfn.IFS(D34= ""," ",D34<> " ",F34*(G34/H34)),"")} -> 0
A35: BEL | B35: 2011 | D35: - | E35: {=_xlfn.IFS(D35=policy_name_clustering!$A$2,policy_name_clustering!$C$2,D35=policy_name_clustering!$A$3,policy_name_clustering!$C$3,D35=policy_name_clustering!$A$4,policy_name_clustering!$C$4,D35=policy_name_clustering!$A$5,policy_name_clustering!$C$5,D35=policy_name_clustering!$A$6,policy_name_clustering!$C$6,D35=policy_name_clustering!$A$7,policy_name_clustering!$C$7,D35=policy_name_clustering!$A$8,policy_name_clustering!$C$8,D35=policy_name_clustering!$A$9,policy_name_clustering!$C$9,D35=policy_name_clustering!$A$10,policy_name_clustering!$C$10,D35=policy_name_clustering!$A$11,policy_name_clustering!$C$11,D35=policy_name_clustering!$A$12,policy_name_clustering!$C$12,D35="-","")} | G35: =solar_cum_cap!C37 -> 1864.9 | H35: =estimated_capacity!C35 -> 1774.0201 | I35: {=_xlfn.IFS(D35= ""," ",D35<> " ",F35*(G35/H35))} -> 0 | J35: {=_xlfn.IFS(D35= ""," ",D35<> " ",(H35-F35)*(G35/H35))} -> 1864.9 | K35: {=IF(ISNUMBER(H35),_xlfn.IFS(D35= ""," ",D35<> " ",F35*(G35/H35)),"")} -> 0
A36: BEL | B36: 2012 | D36: - | E36: {=_xlfn.IFS(D36=policy_name_clustering!$A$2,policy_name_clustering!$C$2,D36=policy_name_clustering!$A$3,policy_name_clustering!$C$3,D36=policy_name_clustering!$A$4,policy_name_clustering!$C$4,D36=policy_name_clustering!$A$5,policy_name_clustering!$C$5,D36=policy_name_clustering!$A$6,policy_name_clustering!$C$6,D36=policy_name_clustering!$A$7,policy_name_clustering!$C$7,D36=policy_name_clustering!$A$8,policy_name_clustering!$C$8,D36=policy_name_clustering!$A$9,policy_name_clustering!$C$9,D36=policy_name_clustering!$A$10,policy_name_clustering!$C$10,D36=policy_name_clustering!$A$11,policy_name_clustering!$C$11,D36=policy_name_clustering!$A$12,policy_name_clustering!$C$12,D36="-","")} | G36: =solar_cum_cap!C38 -> 2595.5 | H36: =estimated_capacity!C36 -> 2141.7769 | I36: {=_xlfn.IFS(D36= ""," ",D36<> " ",F36*(G36/H36))} -> 0 | J36: {=_xlfn.IFS(D36= ""," ",D36<> " ",(H36-F36)*(G36/H36))} -> 2595.5 | K36: {=IF(ISNUMBER(H36),_xlfn.IFS(D36= ""," ",D36<> " ",F36*(G36/H36)),"")} -> 0
... A47: BEL | B47: 2023 | D47: - | E47: {=_xlfn.IFS(D47=policy_name_clustering!$A$2,policy_name_clustering!$C$2,D47=policy_name_clustering!$A$3,policy_name_clustering!$C$3,D47=policy_name_clustering!$A$4,policy_name_clustering!$C$4,D47=policy_name_clustering!$A$5,policy_name_clustering!$C$5,D47=policy_name_clustering!$A$6,policy_name_clustering!$C$6,D47=policy_name_clustering!$A$7,policy_name_clustering!$C$7,D47=policy_name_clustering!$A$8,policy_name_clustering!$C$8,D47=policy_name_clustering!$A$9,policy_name_clustering!$C$9,D47=policy_name_clustering!$A$10,policy_name_clustering!$C$10,D47=policy_name_clustering!$A$11,policy_name_clustering!$C$11,D47=policy_name_clustering!$A$12,policy_name_clustering!$C$12,D47="-","")} | G47: =solar_cum_cap!C49 -> 8351.9 | H47: =estimated_capacity!C47 -> 7158.506 | I47: {=_xlfn.IFS(D47= ""," ",D47<> " ",F47*(G47/H47))} -> 0 | J47: {=_xlfn.IFS(D47= ""," ",D47<> " ",(H47-F47)*(G47/H47))} -> 8351.9 | K47: {=IF(ISNUMBER(H47),_xlfn.IFS(D47= ""," ",D47<> " ",F47*(G47/H47)),"")} -> 0
A48: BGR | B48: 2003 | D48: - | E48: {=_xlfn.IFS(D48=policy_name_clustering!$A$2,policy_name_clustering!$C$2,D48=policy_name_clustering!$A$3,policy_name_clustering!$C$3,D48=policy_name_clustering!$A$4,policy_name_clustering!$C$4,D48=policy_name_clustering!$A$5,policy_name_clustering!$C$5,D48=policy_name_clustering!$A$6,policy_name_clustering!$C$6,D48=policy_name_clustering!$A$7,policy_name_clustering!$C$7,D48=policy_name_clustering!$A$8,policy_name_clustering!$C$8,D48=policy_name_clustering!$A$9,policy_name_clustering!$C$9,D48=policy_name_clustering!$A$10,policy_name_clustering!$C$10,D48=policy_name_clustering!$A$11,policy_name_clustering!$C$11,D48=policy_name_clustering!$A$12,policy_name_clustering!$C$12,D48="-","")} | G48: =solar_cum_cap!C51 -> 0 | H48: =estimated_capacity!C48 -> -32.808115 | I48: {=_xlfn.IFS(D48= ""," ",D48<> " ",F48*(G48/H48))} -> 0 | J48: {=_xlfn.IFS(D48= ""," ",D48<> " ",(H48-F48)*(G48/H48))} -> 0 | K48: {=IF(ISNUMBER(H48),_xlfn.IFS(D48= ""," ",D48<> " ",F48*(G48/H48)),"")} -> 0
A49: BGR | B49: 2004 | D49: - | E49: {=_xlfn.IFS(D49=policy_name_clustering!$A$2,policy_name_clustering!$C$2,D49=policy_name_clustering!$A$3,policy_name_clustering!$C$3,D49=policy_name_clustering!$A$4,policy_name_clustering!$C$4,D49=policy_name_clustering!$A$5,policy_name_clustering!$C$5,D49=policy_name_clustering!$A$6,policy_name_clustering!$C$6,D49=policy_name_clustering!$A$7,policy_name_clustering!$C$7,D49=policy_name_clustering!$A$8,policy_name_clustering!$C$8,D49=policy_name_clustering!$A$9,policy_name_clustering!$C$9,D49=policy_name_clustering!$A$10,policy_name_clustering!$C$10,D49=policy_name_clustering!$A$11,policy_name_clustering!$C$11,D49=policy_name_clustering!$A$12,policy_name_clustering!$C$12,D49="-","")} | G49: =solar_cum_cap!C52 -> 0 | H49: =estimated_capacity!C49 -> -59.422986 | I49: {=_xlfn.IFS(D49= ""," ",D49<> " ",F49*(G49/H49))} -> 0 | J49: {=_xlfn.IFS(D49= ""," ",D49<> " ",(H49-F49)*(G49/H49))} -> 0 | K49: {=IF(ISNUMBER(H49),_xlfn.IFS(D49= ""," ",D49<> " ",F49*(G49/H49)),"")} -> 0
A50: BGR | B50: 2005 | D50: - | E50: {=_xlfn.IFS(D50=policy_name_clustering!$A$2,policy_name_clustering!$C$2,D50=policy_name_clustering!$A$3,policy_name_clustering!$C$3,D50=policy_name_clustering!$A$4,policy_name_clustering!$C$4,D50=policy_name_clustering!$A$5,policy_name_clustering!$C$5,D50=policy_name_clustering!$A$6,policy_name_clustering!$C$6,D50=policy_name_clustering!$A$7,policy_name_clustering!$C$7,D50=policy_name_clustering!$A$8,policy_name_clustering!$C$8,D50=policy_name_clustering!$A$9,policy_name_clustering!$C$9,D50=policy_name_clustering!$A$10,policy_name_clustering!$C$10,D50=policy_name_clustering!$A$11,policy_name_clustering!$C$11,D50=policy_name_clustering!$A$12,policy_name_clustering!$C$12,D50="-","")} | G50: =solar_cum_cap!C53 -> 0 | H50: =estimated_capacity!C50 -> -94.260044 | I50: {=_xlfn.IFS(D50= ""," ",D50<> " ",F50*(G50/H50))} -> 0 | J50: {=_xlfn.IFS(D50= ""," ",D50<> " ",(H50-F50)*(G50/H50))} -> 0 | K50: {=IF(ISNUMBER(H50),_xlfn.IFS(D50= ""," ",D50<> " ",F50*(G50/H50)),"")} -> 0
A51: BGR | B51: 2006 | D51: - | E51: {=_xlfn.IFS(D51=policy_name_clustering!$A$2,policy_name_clustering!$C$2,D51=policy_name_clustering!$A$3,policy_name_clustering!$C$3,D51=policy_name_clustering!$A$4,policy_name_clustering!$C$4,D51=policy_name_clustering!$A$5,policy_name_clustering!$C$5,D51=policy_name_clustering!$A$6,policy_name_clustering!$C$6,D51=policy_name_clustering!$A$7,policy_name_clustering!$C$7,D51=policy_name_clustering!$A$8,policy_name_clustering!$C$8,D51=policy_name_clustering!$A$9,policy_name_clustering!$C$9,D51=policy_name_clustering!$A$10,policy_name_clustering!$C$10,D51=policy_name_clustering!$A$11,policy_name_clustering!$C$11,D51=policy_name_clustering!$A$12,policy_name_clustering!$C$12,D51="-","")} | G51: =solar_cum_cap!C54 -> 0 | H51: =estimated_capacity!C51 -> -125.53581 | I51: {=_xlfn.IFS(D51= ""," ",D51<> " ",F51*(G51/H51))} -> 0 | J51: {=_xlfn.IFS(D51= ""," ",D51<> " ",(H51-F51)*(G51/H51))} -> 0 | K51: {=IF(ISNUMBER(H51),_xlfn.IFS(D51= ""," ",D51<> " ",F51*(G51/H51)),"")} -> 0
A52: BGR | B52: 2007 | D52: - | E52: {=_xlfn.IFS(D52=policy_name_clustering!$A$2,policy_name_clustering!$C$2,D52=policy_name_clustering!$A$3,policy_name_clustering!$C$3,D52=policy_name_clustering!$A$4,policy_name_clustering!$C$4,D52=policy_name_clustering!$A$5,policy_name_clustering!$C$5,D52=policy_name_clustering!$A$6,policy_name_clustering!$C$6,D52=policy_name_clustering!$A$7,policy_name_clustering!$C$7,D52=policy_name_clustering!$A$8,policy_name_clustering!$C$8,D52=policy_name_clustering!$A$9,policy_name_clustering!$C$9,D52=policy_name_clustering!$A$10,policy_name_clustering!$C$10,D52=policy_name_clustering!$A$11,policy_name_clustering!$C$11,D52=policy_name_clustering!$A$12,policy_name_clustering!$C$12,D52="-","")} | G52: =solar_cum_cap!C55 -> 0 | H52: =estimated_capacity!C52 -> -155.56036 | I52: {=_xlfn.IFS(D52= ""," ",D52<> " ",F52*(G52/H52))} -> 0 | J52: {=_xlfn.IFS(D52= ""," ",D52<> " ",(H52-F52)*(G52/H52))} -> 0 | K52: {=IF(ISNUMBER(H52),_xlfn.IFS(D52= ""," ",D52<> " ",F52*(G52/H52)),"")} -> 0
A53: BGR | B53: 2008 | D53: - | E53: {=_xlfn.IFS(D53=policy_name_clustering!$A$2,policy_name_clustering!$C$2,D53=policy_name_clustering!$A$3,policy_name_clustering!$C$3,D53=policy_name_clustering!$A$4,policy_name_clustering!$C$4,D53=policy_name_clustering!$A$5,policy_name_clustering!$C$5,D53=policy_name_clustering!$A$6,policy_name_clustering!$C$6,D53=policy_name_clustering!$A$7,policy_name_clustering!$C$7,D53=policy_name_clustering!$A$8,policy_name_clustering!$C$8,D53=policy_name_clustering!$A$9,policy_name_clustering!$C$9,D53=policy_name_clustering!$A$10,policy_name_clustering!$C$10,D53=policy_name_clustering!$A$11,policy_name_clustering!$C$11,D53=policy_name_clustering!$A$12,policy_name_clustering!$C$12,D53="-","")} | G53: =solar_cum_cap!C56 -> 0 | H53: =estimated_capacity!C53 -> -157.72615 | I53: {=_xlfn.IFS(D53= ""," ",D53<> " ",F53*(G53/H53))} -> 0 | J53: {=_xlfn.IFS(D53= ""," ",D53<> " ",(H53-F53)*(G53/H53))} -> 0 | K53: {=IF(ISNUMBER(H53),_xlfn.IFS(D53= ""," ",D53<> " ",F53*(G53/H53)),"")} -> 0
A54: BGR | B54: 2009 | D54: - | E54: {=_xlfn.IFS(D54=policy_name_clustering!$A$2,policy_name_clustering!$C$2,D54=policy_name_clustering!$A$3,policy_name_clustering!$C$3,D54=policy_name_clustering!$A$4,policy_name_clustering!$C$4,D54=policy_name_clustering!$A$5,policy_name_clustering!$C$5,D54=policy_name_clustering!$A$6,policy_name_clustering!$C$6,D54=policy_name_clustering!$A$7,policy_name_clustering!$C$7,D54=policy_name_clustering!$A$8,policy_name_clustering!$C$8,D54=policy_name_clustering!$A$9,policy_name_clustering!$C$9,D54=policy_name_clustering!$A$10,policy_name_clustering!$C$10,D54=policy_name_clustering!$A$11,policy_name_clustering!$C$11,D54=policy_name_clustering!$A$12,policy_name_clustering!$C$12,D54="-","")} | G54: =solar_cum_cap!C57 -> 2 | H54: =estimated_capacity!C54 -> -119.26938 | I54: {=_xlfn.IFS(D54= ""," ",D54<> " ",F54*(G54/H54))} -> 0 | J54: {=_xlfn.IFS(D54= ""," ",D54<> " ",(H54-F54)*(G54/H54))} -> 2 | K54: {=IF(ISNUMBER(H54),_xlfn.IFS(D54= ""," ",D54<> " ",F54*(G54/H54)),"")} -> 0
A55: BGR | B55: 2010 | D55: - | E55: {=_xlfn.IFS(D55=policy_name_clustering!$A$2,policy_name_clustering!$C$2,D55=policy_name_clustering!$A$3,policy_name_clustering!$C$3,D55=policy_name_clustering!$A$4,policy_name_clustering!$C$4,D55=policy_name_clustering!$A$5,policy_name_clustering!$C$5,D55=policy_name_clustering!$A$6,policy_name_clustering!$C$6,D55=policy_name_clustering!$A$7,policy_name_clustering!$C$7,D55=policy_name_clustering!$A$8,policy_name_clustering!$C$8,D55=policy_name_clustering!$A$9,policy_name_clustering!$C$9,D55=policy_name_clustering!$A$10,policy_name_clustering!$C$10,D55=policy_name_clustering!$A$11,policy_name_clustering!$C$11,D55=policy_name_clustering!$A$12,policy_name_clustering!$C$12,D55="-","")} | G55: =solar_cum_cap!C58 -> 25 | H55: =estimated_capacity!C55 -> -46.850379 | I55: {=_xlfn.IFS(D55= ""," ",D55<> " ",F55*(G55/H55))} -> 0 | J55: {=_xlfn.IFS(D55= ""," ",D55<> " ",(H55-F55)*(G55/H55))} -> 25 | K55: {=IF(ISNUMBER(H55),_xlfn.IFS(D55= ""," ",D55<> " ",F55*(G55/H55)),"")} -> 0
A56: BGR | B56: 2011 | D56: - | E56: {=_xlfn.IFS(D56=policy_name_clustering!$A$2,policy_name_clustering!$C$2,D56=policy_name_clustering!$A$3,policy_name_clustering!$C$3,D56=policy_name_clustering!$A$4,policy_name_clustering!$C$4,D56=policy_name_clustering!$A$5,policy_name_clustering!$C$5,D56=policy_name_clustering!$A$6,policy_name_clustering!$C$6,D56=policy_name_clustering!$A$7,policy_name_clustering!$C$7,D56=policy_name_clustering!$A$8,policy_name_clustering!$C$8,D56=policy_name_clustering!$A$9,policy_name_clustering!$C$9,D56=policy_name_clustering!$A$10,policy_name_clustering!$C$10,D56=policy_name_clustering!$A$11,policy_name_clustering!$C$11,D56=policy_name_clustering!$A$12,policy_name_clustering!$C$12,D56="-","")} | G56: =solar_cum_cap!C59 -> 154 | H56: =estimated_capacity!C56 -> 55.785768 | I56: {=_xlfn.IFS(D56= ""," ",D56<> " ",F56*(G56/H56))} -> 0 | J56: {=_xlfn.IFS(D56= ""," ",D56<> " ",(H56-F56)*(G56/H56))} -> 154 | K56: {=IF(ISNUMBER(H56),_xlfn.IFS(D56= ""," ",D56<> " ",F56*(G56/H56)),"")} -> 0
A57: BGR | B57: 2012 | D57: - | E57: {=_xlfn.IFS(D57=policy_name_clustering!$A$2,policy_name_clustering!$C$2,D57=policy_name_clustering!$A$3,policy_name_clustering!$C$3,D57=policy_name_clustering!$A$4,policy_name_clustering!$C$4,D57=policy_name_clustering!$A$5,policy_name_clustering!$C$5,D57=policy_name_clustering!$A$6,policy_name_clustering!$C$6,D57=policy_name_clustering!$A$7,policy_name_clustering!$C$7,D57=policy_name_clustering!$A$8,policy_name_clustering!$C$8,D57=policy_name_clustering!$A$9,policy_name_clustering!$C$9,D57=policy_name_clustering!$A$10,policy_name_clustering!$C$10,D57=policy_name_clustering!$A$11,policy_name_clustering!$C$11,D57=policy_name_clustering!$A$12,policy_name_clustering!$C$12,D57="-","")} | G57: =solar_cum_cap!C60 -> 921.987 | H57: =estimated_capacity!C57 -> 204.26346 | I57: {=_xlfn.IFS(D57= ""," ",D57<> " ",F57*(G57/H57))} -> 0 | J57: {=_xlfn.IFS(D57= ""," ",D57<> " ",(H57-F57)*(G57/H57))} -> 921.987 | K57: {=IF(ISNUMBER(H57),_xlfn.IFS(D57= ""," ",D57<> " ",F57*(G57/H57)),"")} -> 0
A58: BGR | B58: 2013 | D58: - | E58: {=_xlfn.IFS(D58=policy_name_clustering!$A$2,policy_name_clustering!$C$2,D58=policy_name_clustering!$A$3,policy_name_clustering!$C$3,D58=policy_name_clustering!$A$4,policy_name_clustering!$C$4,D58=policy_name_clustering!$A$5,policy_name_clustering!$C$5,D58=policy_name_clustering!$A$6,policy_name_clustering!$C$6,D58=policy_name_clustering!$A$7,policy_name_clustering!$C$7,D58=policy_name_clustering!$A$8,policy_name_clustering!$C$8,D58=policy_name_clustering!$A$9,policy_name_clustering!$C$9,D58=policy_name_clustering!$A$10,policy_name_clustering!$C$10,D58=policy_name_clustering!$A$11,policy_name_clustering!$C$11,D58=policy_name_clustering!$A$12,policy_name_clustering!$C$12,D58="-","")} | G58: =solar_cum_cap!C61 -> 1038.535 | H58: =estimated_capacity!C58 -> 388.39182 | I58: {=_xlfn.IFS(D58= ""," ",D58<> " ",F58*(G58/H58))} -> 0 | J58: {=_xlfn.IFS(D58= ""," ",D58<> " ",(H58-F58)*(G58/H58))} -> 1038.535 | K58: {=IF(ISNUMBER(H58),_xlfn.IFS(D58= ""," ",D58<> " ",F58*(G58/H58)),"")} -> 0
A59: BGR | B59: 2014 | D59: - | E59: {=_xlfn.IFS(D59=policy_name_clustering!$A$2,policy_name_clustering!$C$2,D59=policy_name_clustering!$A$3,policy_name_clustering!$C$3,D59=policy_name_clustering!$A$4,policy_name_clustering!$C$4,D59=policy_name_clustering!$A$5,policy_name_clustering!$C$5,D59=policy_name_clustering!$A$6,policy_name_clustering!$C$6,D59=policy_name_clustering!$A$7,policy_name_clustering!$C$7,D59=policy_name_clustering!$A$8,policy_name_clustering!$C$8,D59=policy_name_clustering!$A$9,policy_name_clustering!$C$9,D59=policy_name_clustering!$A$10,policy_name_clustering!$C$10,D59=policy_name_clustering!$A$11,policy_name_clustering!$C$11,D59=policy_name_clustering!$A$12,policy_name_clustering!$C$12,D59="-","")} | G59: =solar_cum_cap!C62 -> 1028.917 | H59: =estimated_capacity!C59 -> 609.73284 | I59: {=_xlfn.IFS(D59= ""," ",D59<> " ",F59*(G59/H59))} -> 0 | J59: {=_xlfn.IFS(D59= ""," ",D59<> " ",(H59-F59)*(G59/H59))} -> 1028.917 | K59: {=IF(ISNUMBER(H59),_xlfn.IFS(D59= ""," ",D59<> " ",F59*(G59/H59)),"")} -> 0
... A68: BGR | B68: 2023 | D68: - | E68: {=_xlfn.IFS(D68=policy_name_clustering!$A$2,policy_name_clustering!$C$2,D68=policy_name_clustering!$A$3,policy_name_clustering!$C$3,D68=policy_name_clustering!$A$4,policy_name_clustering!$C$4,D68=policy_name_clustering!$A$5,policy_name_clustering!$C$5,D68=policy_name_clustering!$A$6,policy_name_clustering!$C$6,D68=policy_name_clustering!$A$7,policy_name_clustering!$C$7,D68=policy_name_clustering!$A$8,policy_name_clustering!$C$8,D68=policy_name_clustering!$A$9,policy_name_clustering!$C$9,D68=policy_name_clustering!$A$10,policy_name_clustering!$C$10,D68=policy_name_clustering!$A$11,policy_name_clustering!$C$11,D68=policy_name_clustering!$A$12,policy_name_clustering!$C$12,D68="-","")} | G68: =solar_cum_cap!C71 -> 2908.127 | H68: =estimated_capacity!C68 -> 2507.3816 | I68: {=_xlfn.IFS(D68= ""," ",D68<> " ",F68*(G68/H68))} -> 0 | J68: {=_xlfn.IFS(D68= ""," ",D68<> " ",(H68-F68)*(G68/H68))} -> 2908.127 | K68: {=IF(ISNUMBER(H68),_xlfn.IFS(D68= ""," ",D68<> " ",F68*(G68/H68)),"")} -> 0
...

Sheet cumulative_effects
A1: policy instrument | B1: error-adjusted Cumulative policy instrument effect in GW
A2: FiT | B2: =SUMIFS(effect_quant_by_period!$I$2:$I$506,effect_quant_by_period!$D$2:$D$506,A2,effect_quant_by_period!$B$2:$B$506,estimated_capacity!$L$1)/1000 -> 67.74148
A3: FiT level increased | B3: =SUMIFS(effect_quant_by_period!$I$2:$I$506,effect_quant_by_period!$D$2:$D$506,A3,effect_quant_by_period!$B$2:$B$506,estimated_capacity!$L$1)/1000 -> 3.771609
A4: FiT level increased, FiP level increased | B4: =SUMIFS(effect_quant_by_period!$I$2:$I$506,effect_quant_by_period!$D$2:$D$506,A4,effect_quant_by_period!$B$2:$B$506,estimated_capacity!$L$1)/1000 -> 4.7516627
A5: FiP, TGC aim increase | B5: =SUMIFS(effect_quant_by_period!$I$2:$I$506,effect_quant_by_period!$D$2:$D$506,A5,effect_quant_by_period!$B$2:$B$506,estimated_capacity!$L$1)/1000 -> 18.390535
A6: tax incentive increase | B6: =SUMIFS(effect_quant_by_period!$I$2:$I$506,effect_quant_by_period!$D$2:$D$506,A6,effect_quant_by_period!$B$2:$B$506,estimated_capacity!$L$1)/1000 -> 13.122246
A7: FiT prolonged, Tax incentive prolonged, Tender | B7: =SUMIFS(effect_quant_by_period!$I$2:$I$506,effect_quant_by_period!$D$2:$D$506,A7,effect_quant_by_period!$B$2:$B$506,estimated_capacity!$L$1)/1000 -> 13.691958
A8: Tender | B8: =SUMIFS(effect_quant_by_period!$I$2:$I$506,effect_quant_by_period!$D$2:$D$506,A8,effect_quant_by_period!$B$2:$B$506,estimated_capacity!$L$1)/1000 -> 41.880652
A9: Soft loan, Tender | B9: =SUMIFS(effect_quant_by_period!$I$2:$I$506,effect_quant_by_period!$D$2:$D$506,A9,effect_quant_by_period!$B$2:$B$506,estimated_capacity!$L$1)/1000 -> 24.73261
A10: Tender, FiP | B10: =SUMIFS(effect_quant_by_period!$I$2:$I$506,effect_quant_by_period!$D$2:$D$506,A10,effect_quant_by_period!$B$2:$B$506,estimated_capacity!$L$1)/1000 -> 6.720556
A11: Soft loan, FiP, Tender | B11: =SUMIFS(effect_quant_by_period!$I$2:$I$506,effect_quant_by_period!$D$2:$D$506,A11,effect_quant_by_period!$B$2:$B$506,estimated_capacity!$L$1)/1000 -> 11.094588
A12: Total policy effect | B12: =SUM(B2:B11) -> 205.8979
A13: Non-policy factors | B13: =SUMIFS(effect_quant_by_period!$J$2:$J$498,effect_quant_by_period!$B$2:$B$498,estimated_capacity!$L$1)/1000 -> 50.124984 | C13: =(estimated_capacity!G2)-B12-B13 -> -8.2150493 | D13: difference as model estimated cumulative capacity is not error adjusted!
A14: Policy effect share | B14: =B12/SUM(B12:B13) -> 0.80421678
A18: policy instrument | B18: error-adjusted Cumulative policy instrument effect in GW
A19: FiT/FiP-based | B19: =SUM(B2:B4) -> 76.264752
A20: Tax-based | B20: =SUM(B6) -> 13.122246
A21: Tender-based | B21: =SUM(B8) -> 41.880652
A22: Policy mix | B22: =SUM(B7,B9,B11,B5) -> 67.90969
A23: Other single instrument | B23: =SUM(B10) -> 6.720556
A24: Total policy effect | B24: =B12 -> 205.8979
A25: Non-policy factors | B25: =B13 -> 50.124984

Sheet policy_contributions_cum
A1: id | B1: time | C1: policy | D1: effect_mw | E1: benchmark_mw | F1: cumulative_effect_mw
A2: DEU | B2: 2004 | C2: effect_tisDEU.2004 | D2: 214.54302 | E2: 406.9602 | F2: 214.54302
A3: DEU | B3: 2005 | C3: effect_tisDEU.2004 | D3: 522.83169 | E3: 718.49486 | F3: 737.37471
A4: DEU | B4: 2006 | C4: effect_tisDEU.2004 | D4: 974.95085 | E4: 1179.0671 | F4: 1712.3256
A5: DEU | B5: 2007 | C5: effect_tisDEU.2004 | D5: 1615.6704 | E5: 1823.1247 | F5: 3327.996
A6: DEU | B6: 2008 | C6: effect_tisDEU.2004 | D6: 2585.2388 | E6: 2806.7767 | F6: 5913.2348
A7: DEU | B7: 2009 | C7: effect_tisDEU.2004 | D7: 3849.6116 | E7: 4063.9566 | F7: 9762.8464
A8: DEU | B8: 2010 | C8: effect_tisDEU.2004 | D8: 6333.6344 | E8: 6607.4063 | F8: 16096.481
A9: DEU | B9: 2011 | C9: effect_tisDEU.2004 | D9: 10211.357 | E9: 10546.33 | F9: 26307.838
A10: DEU | B10: 2012 | C10: effect_tisDEU.2004 | D10: 5451.9404 | E10: 5375.5431 | F10: 31759.778
A11: DEU | B11: 2013 | C11: effect_tisDEU.2004 | D11: 3206.7747 | E11: 2988.3031 | F11: 34966.553
A12: DEU | B12: 2014 | C12: effect_tisDEU.2004 | D12: 1675.5024 | E12: 1394.667 | F12: 36642.055
A13: DEU | B13: 2015 | C13: effect_tisDEU.2004 | D13: 1788.3217 | E13: 1498.415 | F13: 38430.377
... A142: POL | B142: 2023 | C142: effect_tisPOL.2018 | D142: 7227.9413 | E142: 7649.0141 | F142: 16025.468

Sheet solar_cum_cap
A1: year | B1: country | C1: solar.cap | E1: Eur_cum_cap_solar_GW | G1: end sample year | H1: 2023
A2: 2000 | B2: AUT | C2: 5 | E2: =SUMIF($A$2:$A$466,$H$1,$C$2:$C$466)/1000 -> 256.02288
A3: 2001 | B3: AUT | C3: 7
A4: 2002 | B4: AUT | C4: 9
A5: 2003 | B5: AUT | C5: 23
A6: 2004 | B6: AUT | C6: 27
A7: 2005 | B7: AUT | C7: 21.018
A8: 2006 | B8: AUT | C8: 22.387
A9: 2007 | B9: AUT | C9: 24.238
A10: 2008 | B10: AUT | C10: 30.12
A11: 2009 | B11: AUT | C11: 48.915
A12: 2010 | B12: AUT | C12: 88.813
A13: 2011 | B13: AUT | C13: 174.07
A14: 2012 | B14: AUT | C14: 337.483
... A466: 2023 | B466: SWE | C466: 3993

Sheet estimated_capacity
A1: id | B1: time | C1: estimated_cumulative_solar_cap_MW | G1: Eur_estimated_cum_cap_GW | K1: end sample year | L1: 2023
A2: AUT | B2: 2001 | C2: 37.662573 | G2: =SUMIF(B2:B446,$L$1,C2:C446)/1000 -> 247.80783
A3: AUT | B3: 2002 | C3: 67.605946
A4: AUT | B4: 2003 | C4: 111.45853
A5: AUT | B5: 2004 | C5: 179.5902
A6: AUT | B6: 2005 | C6: 248.19562
A7: AUT | B7: 2006 | C7: 322.68046
A8: AUT | B8: 2007 | C8: 402.12565
A9: AUT | B9: 2008 | C9: 499.52628
A10: AUT | B10: 2009 | C10: 601.77341
A11: AUT | B11: 2010 | C11: 745.20818
A12: AUT | B12: 2011 | C12: 942.06133
A13: AUT | B13: 2012 | C13: 1181.3722
A14: AUT | B14: 2013 | C14: 1478.0097
... A446: SWE | B446: 2023 | C446: 3227.1494

Sheet policy_name_clustering
A1: full name | B1: dominant instrument | C1: cluster name
A2: FiT | B2: FiT | C2: FiT/FiP-based
A3: FiT level increased | B3: FiT | C3: FiT/FiP-based
A4: FiT prolonged, Tax incentive prolonged, Tender | B4: FiT | C4: Policy mix
A5: FiT level increased, FiP level increased | B5: FiT | C5: FiT/FiP-based
A6: FiP, TGC aim increase | B6: FiP | C6: Policy mix
A7: Tax incentive increase | B7: Tax incentive | C7: Tax-based
A8: Tender | B8: Tender | C8: Tender-based
A9: Soft loan, Tender | B9: Tender | C9: Policy mix
A10: Tender, FiP | B10: Tender | C10: Other single instrument
A11: Soft loan, FiP, Tender | B11: Tender | C11: Policy mix
A12: Tender, FiT level increased, Tax incentive prolonged | B12: Tender | C12: Policy mix
