Workbook

Sheet effect_quant_by_period
A1: id | B1: time | C1: policy details | D1: policy effects and effect duration | E1: policy_group_name | F1: cumulative_policy_effect_mw | G1: observed cumulative MW deployed | H1: estimated cumulative MW deployed | I1: error-adjusted total policy effect in MW | J1: error-adjusted non-policy & unidentified policy effect in MW | K1: cumulative error-adjusted total policy mix effect in MW
A2: AUT | B2: 1991 | D2: - | E2: {=_xlfn.IFS(D2=policy_name_clustering!$A$2,policy_name_clustering!$C$2,D2=policy_name_clustering!$A$3,policy_name_clustering!$C$3,D2=policy_name_clustering!$A$5,policy_name_clustering!$C$5,D2=policy_name_clustering!$A$6,policy_name_clustering!$C$6,D2=policy_name_clustering!$A$7,policy_name_clustering!$C$7,D2=policy_name_clustering!$A$8,policy_name_clustering!$C$8,D2=policy_name_clustering!$A$9,policy_name_clustering!$C$9,D2=policy_name_clustering!$A$10,policy_name_clustering!$C$10,D2=policy_name_clustering!$A$11,policy_name_clustering!$C$11,D2=policy_name_clustering!$A$12,policy_name_clustering!$C$12,D2=policy_name_clustering!$A$13,policy_name_clustering!$C$13,D2=policy_name_clustering!$A$14,policy_name_clustering!$C$14,D2=policy_name_clustering!$A$15,policy_name_clustering!$C$15,D2=policy_name_clustering!$A$16,policy_name_clustering!$C$16,D2="-","",D2=policy_name_clustering!$A$4,policy_name_clustering!$C$4)} | G2: =wind_cump_cap!C3 -> 0 | H2: =estimated_capacity!C2 -> -8.2265578 | I2: {=_xlfn.IFS(D2= ""," ",D2<> " ",F2*(G2/H2))} -> 0 | J2: {=_xlfn.IFS(D2= ""," ",D2<> " ",(H2-F2)*(G2/H2))} -> 0 | K2: {=IF(ISNUMBER(H2),_xlfn.IFS(D2= ""," ",D2<> " ",F2*(G2/H2)),"")} -> 0
A3: AUT | B3: 1992 | D3: - | E3: {=_xlfn.IFS(D3=policy_name_clustering!$A$2,policy_name_clustering!$C$2,D3=policy_name_clustering!$A$3,policy_name_clustering!$C$3,D3=policy_name_clustering!$A$5,policy_name_clustering!$C$5,D3=policy_name_clustering!$A$6,policy_name_clustering!$C$6,D3=policy_name_clustering!$A$7,policy_name_clustering!$C$7,D3=policy_name_clustering!$A$8,policy_name_clustering!$C$8,D3=policy_name_clustering!$A$9,policy_name_clustering!$C$9,D3=policy_name_clustering!$A$10,policy_name_clustering!$C$10,D3=policy_name_clustering!$A$11,policy_name_clustering!$C$11,D3=policy_name_clustering!$A$12,policy_name_clustering!$C$12,D3=policy_name_clustering!$A$13,policy_name_clustering!$C$13,D3=policy_name_clustering!$A$14,policy_name_clustering!$C$14,D3=policy_name_clustering!$A$15,policy_name_clustering!$C$15,D3=policy_name_clustering!$A$16,policy_name_clustering!$C$16,D3="-","",D3=policy_name_clustering!$A$4,policy_name_clustering!$C$4)} | G3: =wind_cump_cap!C4 -> 0 | H3: =estimated_capacity!C3 -> -12.430992 | I3: {=_xlfn.IFS(D3= ""," ",D3<> " ",F3*(G3/H3))} -> 0 | J3: {=_xlfn.IFS(D3= ""," ",D3<> " ",(H3-F3)*(G3/H3))} -> 0 | K3: {=IF(ISNUMBER(H3),_xlfn.IFS(D3= ""," ",D3<> " ",F3*(G3/H3)),"")} -> 0
A4: AUT | B4: 1993 | D4: - | E4: {=_xlfn.IFS(D4=policy_name_clustering!$A$2,policy_name_clustering!$C$2,D4=policy_name_clustering!$A$3,policy_name_clustering!$C$3,D4=policy_name_clustering!$A$5,policy_name_clustering!$C$5,D4=policy_name_clustering!$A$6,policy_name_clustering!$C$6,D4=policy_name_clustering!$A$7,policy_name_clustering!$C$7,D4=policy_name_clustering!$A$8,policy_name_clustering!$C$8,D4=policy_name_clustering!$A$9,policy_name_clustering!$C$9,D4=policy_name_clustering!$A$10,policy_name_clustering!$C$10,D4=policy_name_clustering!$A$11,policy_name_clustering!$C$11,D4=policy_name_clustering!$A$12,policy_name_clustering!$C$12,D4=policy_name_clustering!$A$13,policy_name_clustering!$C$13,D4=policy_name_clustering!$A$14,policy_name_clustering!$C$14,D4=policy_name_clustering!$A$15,policy_name_clustering!$C$15,D4=policy_name_clustering!$A$16,policy_name_clustering!$C$16,D4="-","",D4=policy_name_clustering!$A$4,policy_name_clustering!$C$4)} | G4: =wind_cump_cap!C5 -> 1 | H4: =estimated_capacity!C4 -> -10.517072 | I4: {=_xlfn.IFS(D4= ""," ",D4<> " ",F4*(G4/H4))} -> 0 | J4: {=_xlfn.IFS(D4= ""," ",D4<> " ",(H4-F4)*(G4/H4))} -> 1 | K4: {=IF(ISNUMBER(H4),_xlfn.IFS(D4= ""," ",D4<> " ",F4*(G4/H4)),"")} -> 0
A5: AUT | B5: 1994 | D5: - | E5: {=_xlfn.IFS(D5=policy_name_clustering!$A$2,policy_name_clustering!$C$2,D5=policy_name_clustering!$A$3,policy_name_clustering!$C$3,D5=policy_name_clustering!$A$5,policy_name_clustering!$C$5,D5=policy_name_clustering!$A$6,policy_name_clustering!$C$6,D5=policy_name_clustering!$A$7,policy_name_clustering!$C$7,D5=policy_name_clustering!$A$8,policy_name_clustering!$C$8,D5=policy_name_clustering!$A$9,policy_name_clustering!$C$9,D5=policy_name_clustering!$A$10,policy_name_clustering!$C$10,D5=policy_name_clustering!$A$11,policy_name_clustering!$C$11,D5=policy_name_clustering!$A$12,policy_name_clustering!$C$12,D5=policy_name_clustering!$A$13,policy_name_clustering!$C$13,D5=policy_name_clustering!$A$14,policy_name_clustering!$C$14,D5=policy_name_clustering!$A$15,policy_name_clustering!$C$15,D5=policy_name_clustering!$A$16,policy_name_clustering!$C$16,D5="-","",D5=policy_name_clustering!$A$4,policy_name_clustering!$C$4)} | G5: =wind_cump_cap!C6 -> 1 | H5: =estimated_capacity!C5 -> -4.4677335 | I5: {=_xlfn.IFS(D5= ""," ",D5<> " ",F5*(G5/H5))} -> 0 | J5: {=_xlfn.IFS(D5= ""," ",D5<> " ",(H5-F5)*(G5/H5))} -> 1 | K5: {=IF(ISNUMBER(H5),_xlfn.IFS(D5= ""," ",D5<> " ",F5*(G5/H5)),"")} -> 0
A6: AUT | B6: 1995 | D6: - | E6: {=_xlfn.IFS(D6=policy_name_clustering!$A$2,policy_name_clustering!$C$2,D6=policy_name_clustering!$A$3,policy_name_clustering!$C$3,D6=policy_name_clustering!$A$5,policy_name_clustering!$C$5,D6=policy_name_clustering!$A$6,policy_name_clustering!$C$6,D6=policy_name_clustering!$A$7,policy_name_clustering!$C$7,D6=policy_name_clustering!$A$8,policy_name_clustering!$C$8,D6=policy_name_clustering!$A$9,policy_name_clustering!$C$9,D6=policy_name_clustering!$A$10,policy_name_clustering!$C$10,D6=policy_name_clustering!$A$11,policy_name_clustering!$C$11,D6=policy_name_clustering!$A$12,policy_name_clustering!$C$12,D6=policy_name_clustering!$A$13,policy_name_clustering!$C$13,D6=policy_name_clustering!$A$14,policy_name_clustering!$C$14,D6=policy_name_clustering!$A$15,policy_name_clustering!$C$15,D6=policy_name_clustering!$A$16,policy_name_clustering!$C$16,D6="-","",D6=policy_name_clustering!$A$4,policy_name_clustering!$C$4)} | G6: =wind_cump_cap!C7 -> 1 | H6: =estimated_capacity!C6 -> 13.625984 | I6: {=_xlfn.IFS(D6= ""," ",D6<> " ",F6*(G6/H6))} -> 0 | J6: {=_xlfn.IFS(D6= ""," ",D6<> " ",(H6-F6)*(G6/H6))} -> 1 | K6: {=IF(ISNUMBER(H6),_xlfn.IFS(D6= ""," ",D6<> " ",F6*(G6/H6)),"")} -> 0
A7: AUT | B7: 1996 | D7: - | E7: {=_xlfn.IFS(D7=policy_name_clustering!$A$2,policy_name_clustering!$C$2,D7=policy_name_clustering!$A$3,policy_name_clustering!$C$3,D7=policy_name_clustering!$A$5,policy_name_clustering!$C$5,D7=policy_name_clustering!$A$6,policy_name_clustering!$C$6,D7=policy_name_clustering!$A$7,policy_name_clustering!$C$7,D7=policy_name_clustering!$A$8,policy_name_clustering!$C$8,D7=policy_name_clustering!$A$9,policy_name_clustering!$C$9,D7=policy_name_clustering!$A$10,policy_name_clustering!$C$10,D7=policy_name_clustering!$A$11,policy_name_clustering!$C$11,D7=policy_name_clustering!$A$12,policy_name_clustering!$C$12,D7=policy_name_clustering!$A$13,policy_name_clustering!$C$13,D7=policy_name_clustering!$A$14,policy_name_clustering!$C$14,D7=policy_name_clustering!$A$15,policy_name_clustering!$C$15,D7=policy_name_clustering!$A$16,policy_name_clustering!$C$16,D7="-","",D7=policy_name_clustering!$A$4,policy_name_clustering!$C$4)} | G7: =wind_cump_cap!C8 -> 3 | H7: =estimated_capacity!C7 -> 41.36612 | I7: {=_xlfn.IFS(D7= ""," ",D7<> " ",F7*(G7/H7))} -> 0 | J7: {=_xlfn.IFS(D7= ""," ",D7<> " ",(H7-F7)*(G7/H7))} -> 3 | K7: {=IF(ISNUMBER(H7),_xlfn.IFS(D7= ""," ",D7<> " ",F7*(G7/H7)),"")} -> 0
A8: AUT | B8: 1997 | D8: - | E8: {=_xlfn.IFS(D8=policy_name_clustering!$A$2,policy_name_clustering!$C$2,D8=policy_name_clustering!$A$3,policy_name_clustering!$C$3,D8=policy_name_clustering!$A$5,policy_name_clustering!$C$5,D8=policy_name_clustering!$A$6,policy_name_clustering!$C$6,D8=policy_name_clustering!$A$7,policy_name_clustering!$C$7,D8=policy_name_clustering!$A$8,policy_name_clustering!$C$8,D8=policy_name_clustering!$A$9,policy_name_clustering!$C$9,D8=policy_name_clustering!$A$10,policy_name_clustering!$C$10,D8=policy_name_clustering!$A$11,policy_name_clustering!$C$11,D8=policy_name_clustering!$A$12,policy_name_clustering!$C$12,D8=policy_name_clustering!$A$13,policy_name_clustering!$C$13,D8=policy_name_clustering!$A$14,policy_name_clustering!$C$14,D8=policy_name_clustering!$A$15,policy_name_clustering!$C$15,D8=policy_name_clustering!$A$16,policy_name_clustering!$C$16,D8="-","",D8=policy_name_clustering!$A$4,policy_name_clustering!$C$4)} | G8: =wind_cump_cap!C9 -> 15 | H8: =estimated_capacity!C8 -> 81.797647 | I8: {=_xlfn.IFS(D8= ""," ",D8<> " ",F8*(G8/H8))} -> 0 | J8: {=_xlfn.IFS(D8= ""," ",D8<> " ",(H8-F8)*(G8/H8))} -> 15 | K8: {=IF(ISNUMBER(H8),_xlfn.IFS(D8= ""," ",D8<> " ",F8*(G8/H8)),"")} -> 0
A9: AUT | B9: 1998 | D9: - | E9: {=_xlfn.IFS(D9=policy_name_clustering!$A$2,policy_name_clustering!$C$2,D9=policy_name_clustering!$A$3,policy_name_clustering!$C$3,D9=policy_name_clustering!$A$5,policy_name_clustering!$C$5,D9=policy_name_clustering!$A$6,policy_name_clustering!$C$6,D9=policy_name_clustering!$A$7,policy_name_clustering!$C$7,D9=policy_name_clustering!$A$8,policy_name_clustering!$C$8,D9=policy_name_clustering!$A$9,policy_name_clustering!$C$9,D9=policy_name_clustering!$A$10,policy_name_clustering!$C$10,D9=policy_name_clustering!$A$11,policy_name_clustering!$C$11,D9=policy_name_clustering!$A$12,policy_name_clustering!$C$12,D9=policy_name_clustering!$A$13,policy_name_clustering!$C$13,D9=policy_name_clustering!$A$14,policy_name_clustering!$C$14,D9=policy_name_clustering!$A$15,policy_name_clustering!$C$15,D9=policy_name_clustering!$A$16,policy_name_clustering!$C$16,D9="-","",D9=policy_name_clustering!$A$4,policy_name_clustering!$C$4)} | G9: =wind_cump_cap!C10 -> 34 | H9: =estimated_capacity!C9 -> 125.66332 | I9: {=_xlfn.IFS(D9= ""," ",D9<> " ",F9*(G9/H9))} -> 0 | J9: {=_xlfn.IFS(D9= ""," ",D9<> " ",(H9-F9)*(G9/H9))} -> 34 | K9: {=IF(ISNUMBER(H9),_xlfn.IFS(D9= ""," ",D9<> " ",F9*(G9/H9)),"")} -> 0
A10: AUT | B10: 1999 | D10: - | E10: {=_xlfn.IFS(D10=policy_name_clustering!$A$2,policy_name_clustering!$C$2,D10=policy_name_clustering!$A$3,policy_name_clustering!$C$3,D10=policy_name_clustering!$A$5,policy_name_clustering!$C$5,D10=policy_name_clustering!$A$6,policy_name_clustering!$C$6,D10=policy_name_clustering!$A$7,policy_name_clustering!$C$7,D10=policy_name_clustering!$A$8,policy_name_clustering!$C$8,D10=policy_name_clustering!$A$9,policy_name_clustering!$C$9,D10=policy_name_clustering!$A$10,policy_name_clustering!$C$10,D10=policy_name_clustering!$A$11,policy_name_clustering!$C$11,D10=policy_name_clustering!$A$12,policy_name_clustering!$C$12,D10=policy_name_clustering!$A$13,policy_name_clustering!$C$13,D10=policy_name_clustering!$A$14,policy_name_clustering!$C$14,D10=policy_name_clustering!$A$15,policy_name_clustering!$C$15,D10=policy_name_clustering!$A$16,policy_name_clustering!$C$16,D10="-","",D10=policy_name_clustering!$A$4,policy_name_clustering!$C$4)} | G10: =wind_cump_cap!C11 -> 38 | H10: =estimated_capacity!C10 -> 181.79522 | I10: {=_xlfn.IFS(D10= ""," ",D10<> " ",F10*(G10/H10))} -> 0 | J10: {=_xlfn.IFS(D10= ""," ",D10<> " ",(H10-F10)*(G10/H10))} -> 38 | K10: {=IF(ISNUMBER(H10),_xlfn.IFS(D10= ""," ",D10<> " ",F10*(G10/H10)),"")} -> 0
A11: AUT | B11: 2000 | D11: - | E11: {=_xlfn.IFS(D11=policy_name_clustering!$A$2,policy_name_clustering!$C$2,D11=policy_name_clustering!$A$3,policy_name_clustering!$C$3,D11=policy_name_clustering!$A$5,policy_name_clustering!$C$5,D11=policy_name_clustering!$A$6,policy_name_clustering!$C$6,D11=policy_name_clustering!$A$7,policy_name_clustering!$C$7,D11=policy_name_clustering!$A$8,policy_name_clustering!$C$8,D11=policy_name_clustering!$A$9,policy_name_clustering!$C$9,D11=policy_name_clustering!$A$10,policy_name_clustering!$C$10,D11=policy_name_clustering!$A$11,policy_name_clustering!$C$11,D11=policy_name_clustering!$A$12,policy_name_clustering!$C$12,D11=policy_name_clustering!$A$13,policy_name_clustering!$C$13,D11=policy_name_clustering!$A$14,policy_name_clustering!$C$14,D11=policy_name_clustering!$A$15,policy_name_clustering!$C$15,D11=policy_name_clustering!$A$16,policy_name_clustering!$C$16,D11="-","",D11=policy_name_clustering!$A$4,policy_name_clustering!$C$4)} | G11: =wind_cump_cap!C12 -> 50 | H11: =estimated_capacity!C11 -> 239.55534 | I11: {=_xlfn.IFS(D11= ""," ",D11<> " ",F11*(G11/H11))} -> 0 | J11: {=_xlfn.IFS(D11= ""," ",D11<> " ",(H11-F11)*(G11/H11))} -> 50 | K11: {=IF(ISNUMBER(H11),_xlfn.IFS(D11= ""," ",D11<> " ",F11*(G11/H11)),"")} -> 0
A12: AUT | B12: 2001 | D12: - | E12: {=_xlfn.IFS(D12=policy_name_clustering!$A$2,policy_name_clustering!$C$2,D12=policy_name_clustering!$A$3,policy_name_clustering!$C$3,D12=policy_name_clustering!$A$5,policy_name_clustering!$C$5,D12=policy_name_clustering!$A$6,policy_name_clustering!$C$6,D12=policy_name_clustering!$A$7,policy_name_clustering!$C$7,D12=policy_name_clustering!$A$8,policy_name_clustering!$C$8,D12=policy_name_clustering!$A$9,policy_name_clustering!$C$9,D12=policy_name_clustering!$A$10,policy_name_clustering!$C$10,D12=policy_name_clustering!$A$11,policy_name_clustering!$C$11,D12=policy_name_clustering!$A$12,policy_name_clustering!$C$12,D12=policy_name_clustering!$A$13,policy_name_clustering!$C$13,D12=policy_name_clustering!$A$14,policy_name_clustering!$C$14,D12=policy_name_clustering!$A$15,policy_name_clustering!$C$15,D12=policy_name_clustering!$A$16,policy_name_clustering!$C$16,D12="-","",D12=policy_name_clustering!$A$4,policy_name_clustering!$C$4)} | G12: =wind_cump_cap!C13 -> 67 | H12: =estimated_capacity!C12 -> 311.97932 | I12: {=_xlfn.IFS(D12= ""," ",D12<> " ",F12*(G12/H12))} -> 0 | J12: {=_xlfn.IFS(D12= ""," ",D12<> " ",(H12-F12)*(G12/H12))} -> 67 | K12: {=IF(ISNUMBER(H12),_xlfn.IFS(D12= ""," ",D12<> " ",F12*(G12/H12)),"")} -> 0
A13: AUT | B13: 2002 | D13: - | E13: {=_xlfn.IFS(D13=policy_name_clustering!$A$2,policy_name_clustering!$C$2,D13=policy_name_clustering!$A$3,policy_name_clustering!$C$3,D13=policy_name_clustering!$A$5,policy_name_clustering!$C$5,D13=policy_name_clustering!$A$6,policy_name_clustering!$C$6,D13=policy_name_clustering!$A$7,policy_name_clustering!$C$7,D13=policy_name_clustering!$A$8,policy_name_clustering!$C$8,D13=policy_name_clustering!$A$9,policy_name_clustering!$C$9,D13=policy_name_clustering!$A$10,policy_name_clustering!$C$10,D13=policy_name_clustering!$A$11,policy_name_clustering!$C$11,D13=policy_name_clustering!$A$12,policy_name_clustering!$C$12,D13=policy_name_clustering!$A$13,policy_name_clustering!$C$13,D13=policy_name_clustering!$A$14,policy_name_clustering!$C$14,D13=policy_name_clustering!$A$15,policy_name_clustering!$C$15,D13=policy_name_clustering!$A$16,policy_name_clustering!$C$16,D13="-","",D13=policy_name_clustering!$A$4,policy_name_clustering!$C$4)} | G13: =wind_cump_cap!C14 -> 109 | H13: =estimated_capacity!C13 -> 386.63779 | I13: {=_xlfn.IFS(D13= ""," ",D13<> " ",F13*(G13/H13))} -> 0 | J13: {=_xlfn.IFS(D13= ""," ",D13<> " ",(H13-F13)*(G13/H13))} -> 109 | K13: {=IF(ISNUMBER(H13),_xlfn.IFS(D13= ""," ",D13<> " ",F13*(G13/H13)),"")} -> 0
... A34: AUT | B34: 2023 | D34: - | E34: {=_xlfn.IFS(D34=policy_name_clustering!$A$2,policy_name_clustering!$C$2,D34=policy_name_clustering!$A$3,policy_name_clustering!$C$3,D34=policy_name_clustering!$A$5,policy_name_clustering!$C$5,D34=policy_name_clustering!$A$6,policy_name_clustering!$C$6,D34=policy_name_clustering!$A$7,policy_name_clustering!$C$7,D34=policy_name_clustering!$A$8,policy_name_clustering!$C$8,D34=policy_name_clustering!$A$9,policy_name_clustering!$C$9,D34=policy_name_clustering!$A$10,policy_name_clustering!$C$10,D34=policy_name_clustering!$A$11,policy_name_clustering!$C$11,D34=policy_name_clustering!$A$12,policy_name_clustering!$C$12,D34=policy_name_clustering!$A$13,policy_name_clustering!$C$13,D34=policy_name_clustering!$A$14,policy_name_clustering!$C$14,D34=policy_name_clustering!$A$15,policy_name_clustering!$C$15,D34=policy_name_clustering!$A$16,policy_name_clustering!$C$16,D34="-","",D34=policy_name_clustering!$A$4,policy_name_clustering!$C$4)} | G34: =wind_cump_cap!C35 -> 3896.294 | H34: =estimated_capacity!C34 -> 3836.5655 | I34: {=_xlfn.IFS(D34= ""," ",D34<> " ",F34*(G34/H34))} -> 0 | J34: {=_xlfn.IFS(D34= ""," ",D34<> " ",(H34-F34)*(G34/H34))} -> 3896.294 | K34: {=IF(ISNUMBER(H34),_xlfn.IFS(D34= ""," ",D34<> " ",F34*(G34/H34)),"")} -> 0
A35: BEL | B35: 1991 | D35: - | E35: {=_xlfn.IFS(D35=policy_name_clustering!$A$2,policy_name_clustering!$C$2,D35=policy_name_clustering!$A$3,policy_name_clustering!$C$3,D35=policy_name_clustering!$A$5,policy_name_clustering!$C$5,D35=policy_name_clustering!$A$6,policy_name_clustering!$C$6,D35=policy_name_clustering!$A$7,policy_name_clustering!$C$7,D35=policy_name_clustering!$A$8,policy_name_clustering!$C$8,D35=policy_name_clustering!$A$9,policy_name_clustering!$C$9,D35=policy_name_clustering!$A$10,policy_name_clustering!$C$10,D35=policy_name_clustering!$A$11,policy_name_clustering!$C$11,D35=policy_name_clustering!$A$12,policy_name_clustering!$C$12,D35=policy_name_clustering!$A$13,policy_name_clustering!$C$13,D35=policy_name_clustering!$A$14,policy_name_clustering!$C$14,D35=policy_name_clustering!$A$15,policy_name_clustering!$C$15,D35=policy_name_clustering!$A$16,policy_name_clustering!$C$16,D35="-","",D35=policy_name_clustering!$A$4,policy_name_clustering!$C$4)} | G35: =wind_cump_cap!C37 -> 5 | H35: =estimated_capacity!C35 -> 2.3630401 | I35: {=_xlfn.IFS(D35= ""," ",D35<> " ",F35*(G35/H35))} -> 0 | J35: {=_xlfn.IFS(D35= ""," ",D35<> " ",(H35-F35)*(G35/H35))} -> 5 | K35: {=IF(ISNUMBER(H35),_xlfn.IFS(D35= ""," ",D35<> " ",F35*(G35/H35)),"")} -> 0
A36: BEL | B36: 1992 | D36: - | E36: {=_xlfn.IFS(D36=policy_name_clustering!$A$2,policy_name_clustering!$C$2,D36=policy_name_clustering!$A$3,policy_name_clustering!$C$3,D36=policy_name_clustering!$A$5,policy_name_clustering!$C$5,D36=policy_name_clustering!$A$6,policy_name_clustering!$C$6,D36=policy_name_clustering!$A$7,policy_name_clustering!$C$7,D36=policy_name_clustering!$A$8,policy_name_clustering!$C$8,D36=policy_name_clustering!$A$9,policy_name_clustering!$C$9,D36=policy_name_clustering!$A$10,policy_name_clustering!$C$10,D36=policy_name_clustering!$A$11,policy_name_clustering!$C$11,D36=policy_name_clustering!$A$12,policy_name_clustering!$C$12,D36=policy_name_clustering!$A$13,policy_name_clustering!$C$13,D36=policy_name_clustering!$A$14,policy_name_clustering!$C$14,D36=policy_name_clustering!$A$15,policy_name_clustering!$C$15,D36=policy_name_clustering!$A$16,policy_name_clustering!$C$16,D36="-","",D36=policy_name_clustering!$A$4,policy_name_clustering!$C$4)} | G36: =wind_cump_cap!C38 -> 5 | H36: =estimated_capacity!C36 -> 7.8625886 | I36: {=_xlfn.IFS(D36= ""," ",D36<> " ",F36*(G36/H36))} -> 0 | J36: {=_xlfn.IFS(D36= ""," ",D36<> " ",(H36-F36)*(G36/H36))} -> 5 | K36: {=IF(ISNUMBER(H36),_xlfn.IFS(D36= ""," ",D36<> " ",F36*(G36/H36)),"")} -> 0
A37: BEL | B37: 1993 | D37: - | E37: {=_xlfn.IFS(D37=policy_name_clustering!$A$2,policy_name_clustering!$C$2,D37=policy_name_clustering!$A$3,policy_name_clustering!$C$3,D37=policy_name_clustering!$A$5,policy_name_clustering!$C$5,D37=policy_name_clustering!$A$6,policy_name_clustering!$C$6,D37=policy_name_clustering!$A$7,policy_name_clustering!$C$7,D37=policy_name_clustering!$A$8,policy_name_clustering!$C$8,D37=policy_name_clustering!$A$9,policy_name_clustering!$C$9,D37=policy_name_clustering!$A$10,policy_name_clustering!$C$10,D37=policy_name_clustering!$A$11,policy_name_clustering!$C$11,D37=policy_name_clustering!$A$12,policy_name_clustering!$C$12,D37=policy_name_clustering!$A$13,policy_name_clustering!$C$13,D37=policy_name_clustering!$A$14,policy_name_clustering!$C$14,D37=policy_name_clustering!$A$15,policy_name_clustering!$C$15,D37=policy_name_clustering!$A$16,policy_name_clustering!$C$16,D37="-","",D37=policy_name_clustering!$A$4,policy_name_clustering!$C$4)} | G37: =wind_cump_cap!C39 -> 5 | H37: =estimated_capacity!C37 -> 21.679653 | I37: {=_xlfn.IFS(D37= ""," ",D37<> " ",F37*(G37/H37))} -> 0 | J37: {=_xlfn.IFS(D37= ""," ",D37<> " ",(H37-F37)*(G37/H37))} -> 5 | K37: {=IF(ISNUMBER(H37),_xlfn.IFS(D37= ""," ",D37<> " ",F37*(G37/H37)),"")} -> 0
A38: BEL | B38: 1994 | D38: - | E38: {=_xlfn.IFS(D38=policy_name_clustering!$A$2,policy_name_clustering!$C$2,D38=policy_name_clustering!$A$3,policy_name_clustering!$C$3,D38=policy_name_clustering!$A$5,policy_name_clustering!$C$5,D38=policy_name_clustering!$A$6,policy_name_clustering!$C$6,D38=policy_name_clustering!$A$7,policy_name_clustering!$C$7,D38=policy_name_clustering!$A$8,policy_name_clustering!$C$8,D38=policy_name_clustering!$A$9,policy_name_clustering!$C$9,D38=policy_name_clustering!$A$10,policy_name_clustering!$C$10,D38=policy_name_clustering!$A$11,policy_name_clustering!$C$11,D38=policy_name_clustering!$A$12,policy_name_clustering!$C$12,D38=policy_name_clustering!$A$13,policy_name_clustering!$C$13,D38=policy_name_clustering!$A$14,policy_name_clustering!$C$14,D38=policy_name_clustering!$A$15,policy_name_clustering!$C$15,D38=policy_name_clustering!$A$16,policy_name_clustering!$C$16,D38="-","",D38=policy_name_clustering!$A$4,policy_name_clustering!$C$4)} | G38: =wind_cump_cap!C40 -> 5 | H38: =estimated_capacity!C38 -> 39.446623 | I38: {=_xlfn.IFS(D38= ""," ",D38<> " ",F38*(G38/H38))} -> 0 | J38: {=_xlfn.IFS(D38= ""," ",D38<> " ",(H38-F38)*(G38/H38))} -> 5 | K38: {=IF(ISNUMBER(H38),_xlfn.IFS(D38= ""," ",D38<> " ",F38*(G38/H38)),"")} -> 0
A39: BEL | B39: 1995 | D39: - | E39: {=_xlfn.IFS(D39=policy_name_clustering!$A$2,policy_name_clustering!$C$2,D39=policy_name_clustering!$A$3,policy_name_clustering!$C$3,D39=policy_name_clustering!$A$5,policy_name_clustering!$C$5,D39=policy_name_clustering!$A$6,policy_name_clustering!$C$6,D39=policy_name_clustering!$A$7,policy_name_clustering!$C$7,D39=policy_name_clustering!$A$8,policy_name_clustering!$C$8,D39=policy_name_clustering!$A$9,policy_name_clustering!$C$9,D39=policy_name_clustering!$A$10,policy_name_clustering!$C$10,D39=policy_name_clustering!$A$11,policy_name_clustering!$C$11,D39=policy_name_clustering!$A$12,policy_name_clustering!$C$12,D39=policy_name_clustering!$A$13,policy_name_clustering!$C$13,D39=policy_name_clustering!$A$14,policy_name_clustering!$C$14,D39=policy_name_clustering!$A$15,policy_name_clustering!$C$15,D39=policy_name_clustering!$A$16,policy_name_clustering!$C$16,D39="-","",D39=policy_name_clustering!$A$4,policy_name_clustering!$C$4)} | G39: =wind_cump_cap!C41 -> 5 | H39: =estimated_capacity!C39 -> 71.635675 | I39: {=_xlfn.IFS(D39= ""," ",D39<> " ",F39*(G39/H39))} -> 0 | J39: {=_xlfn.IFS(D39= ""," ",D39<> " ",(H39-F39)*(G39/H39))} -> 5 | K39: {=IF(ISNUMBER(H39),_xlfn.IFS(D39= ""," ",D39<> " ",F39*(G39/H39)),"")} -> 0
A40: BEL | B40: 1996 | D40: - | E40: {=_xlfn.IFS(D40=policy_name_clustering!$A$2,policy_name_clustering!$C$2,D40=policy_name_clustering!$A$3,policy_name_clustering!$C$3,D40=policy_name_clustering!$A$5,policy_name_clustering!$C$5,D40=policy_name_clustering!$A$6,policy_name_clustering!$C$6,D40=policy_name_clustering!$A$7,policy_name_clustering!$C$7,D40=policy_name_clustering!$A$8,policy_name_clustering!$C$8,D40=policy_name_clustering!$A$9,policy_name_clustering!$C$9,D40=policy_name_clustering!$A$10,policy_name_clustering!$C$10,D40=policy_name_clustering!$A$11,policy_name_clustering!$C$11,D40=policy_name_clustering!$A$12,policy_name_clustering!$C$12,D40=policy_name_clustering!$A$13,policy_name_clustering!$C$13,D40=policy_name_clustering!$A$14,policy_name_clustering!$C$14,D40=policy_name_clustering!$A$15,policy_name_clustering!$C$15,D40=policy_name_clustering!$A$16,policy_name_clustering!$C$16,D40="-","",D40=policy_name_clustering!$A$4,policy_name_clustering!$C$4)} | G40: =wind_cump_cap!C42 -> 5 | H40: =estimated_capacity!C40 -> 115.13255 | I40: {=_xlfn.IFS(D40= ""," ",D40<> " ",F40*(G40/H40))} -> 0 | J40: {=_xlfn.IFS(D40= ""," ",D40<> " ",(H40-F40)*(G40/H40))} -> 5 | K40: {=IF(ISNUMBER(H40),_xlfn.IFS(D40= ""," ",D40<> " ",F40*(G40/H40)),"")} -> 0
A41: BEL | B41: 1997 | D41: - | E41: {=_xlfn.IFS(D41=policy_name_clustering!$A$2,policy_name_clustering!$C$2,D41=policy_name_clustering!$A$3,policy_name_clustering!$C$3,D41=policy_name_clustering!$A$5,policy_name_clustering!$C$5,D41=policy_name_clustering!$A$6,policy_name_clustering!$C$6,D41=policy_name_clustering!$A$7,policy_name_clustering!$C$7,D41=policy_name_clustering!$A$8,policy_name_clustering!$C$8,D41=policy_name_clustering!$A$9,policy_name_clustering!$C$9,D41=policy_name_clustering!$A$10,policy_name_clustering!$C$10,D41=policy_name_clustering!$A$11,policy_name_clustering!$C$11,D41=policy_name_clustering!$A$12,policy_name_clustering!$C$12,D41=policy_name_clustering!$A$13,policy_name_clustering!$C$13,D41=policy_name_clustering!$A$14,policy_name_clustering!$C$14,D41=policy_name_clustering!$A$15,policy_name_clustering!$C$15,D41=policy_name_clustering!$A$16,policy_name_clustering!$C$16,D41="-","",D41=policy_name_clustering!$A$4,policy_name_clustering!$C$4)} | G41: =wind_cump_cap!C43 -> 5 | H41: =estimated_capacity!C41 -> 173.19867 | I41: {=_xlfn.IFS(D41= ""," ",D41<> " ",F41*(G41/H41))} -> 0 | J41: {=_xlfn.IFS(D41= ""," ",D41<> " ",(H41-F41)*(G41/H41))} -> 5 | K41: {=IF(ISNUMBER(H41),_xlfn.IFS(D41= ""," ",D41<> " ",F41*(G41/H41)),"")} -> 0
A42: BEL | B42: 1998 | D42: - | E42: {=_xlfn.IFS(D42=policy_name_clustering!$A$2,policy_name_clustering!$C$2,D42=policy_name_clustering!$A$3,policy_name_clustering!$C$3,D42=policy_name_clustering!$A$5,policy_name_clustering!$C$5,D42=policy_name_clustering!$A$6,policy_name_clustering!$C$6,D42=policy_name_clustering!$A$7,policy_name_clustering!$C$7,D42=policy_name_clustering!$A$8,policy_name_clustering!$C$8,D42=policy_name_clustering!$A$9,policy_name_clustering!$C$9,D42=policy_name_clustering!$A$10,policy_name_clustering!$C$10,D42=policy_name_clustering!$A$11,policy_name_clustering!$C$11,D42=policy_name_clustering!$A$12,policy_name_clustering!$C$12,D42=policy_name_clustering!$A$13,policy_name_clustering!$C$13,D42=policy_name_clustering!$A$14,policy_name_clustering!$C$14,D42=policy_name_clustering!$A$15,policy_name_clustering!$C$15,D42=policy_name_clustering!$A$16,policy_name_clustering!$C$16,D42="-","",D42=policy_name_clustering!$A$4,policy_name_clustering!$C$4)} | G42: =wind_cump_cap!C44 -> 6 | H42: =estimated_capacity!C42 -> 235.0608 | I42: {=_xlfn.IFS(D42= ""," ",D42<> " ",F42*(G42/H42))} -> 0 | J42: {=_xlfn.IFS(D42= ""," ",D42<> " ",(H42-F42)*(G42/H42))} -> 6 | K42: {=IF(ISNUMBER(H42),_xlfn.IFS(D42= ""," ",D42<> " ",F42*(G42/H42)),"")} -> 0
A43: BEL | B43: 1999 | D43: - | E43: {=_xlfn.IFS(D43=policy_name_clustering!$A$2,policy_name_clustering!$C$2,D43=policy_name_clustering!$A$3,policy_name_clustering!$C$3,D43=policy_name_clustering!$A$5,policy_name_clustering!$C$5,D43=policy_name_clustering!$A$6,policy_name_clustering!$C$6,D43=policy_name_clustering!$A$7,policy_name_clustering!$C$7,D43=policy_name_clustering!$A$8,policy_name_clustering!$C$8,D43=policy_name_clustering!$A$9,policy_name_clustering!$C$9,D43=policy_name_clustering!$A$10,policy_name_clustering!$C$10,D43=policy_name_clustering!$A$11,policy_name_clustering!$C$11,D43=policy_name_clustering!$A$12,policy_name_clustering!$C$12,D43=policy_name_clustering!$A$13,policy_name_clustering!$C$13,D43=policy_name_clustering!$A$14,policy_name_clustering!$C$14,D43=policy_name_clustering!$A$15,policy_name_clustering!$C$15,D43=policy_name_clustering!$A$16,policy_name_clustering!$C$16,D43="-","",D43=policy_name_clustering!$A$4,policy_name_clustering!$C$4)} | G43: =wind_cump_cap!C45 -> 10 | H43: =estimated_capacity!C43 -> 310.70789 | I43: {=_xlfn.IFS(D43= ""," ",D43<> " ",F43*(G43/H43))} -> 0 | J43: {=_xlfn.IFS(D43= ""," ",D43<> " ",(H43-F43)*(G43/H43))} -> 10 | K43: {=IF(ISNUMBER(H43),_xlfn.IFS(D43= ""," ",D43<> " ",F43*(G43/H43)),"")} -> 0
A44: BEL | B44: 2000 | D44: - | E44: {=_xlfn.IFS(D44=policy_name_clustering!$A$2,policy_name_clustering!$C$2,D44=policy_name_clustering!$A$3,policy_name_clustering!$C$3,D44=policy_name_clustering!$A$5,policy_name_clustering!$C$5,D44=policy_name_clustering!$A$6,policy_name_clustering!$C$6,D44=policy_name_clustering!$A$7,policy_name_clustering!$C$7,D44=policy_name_clustering!$A$8,policy_name_clustering!$C$8,D44=policy_name_clustering!$A$9,policy_name_clustering!$C$9,D44=policy_name_clustering!$A$10,policy_name_clustering!$C$10,D44=policy_name_clustering!$A$11,policy_name_clustering!$C$11,D44=policy_name_clustering!$A$12,policy_name_clustering!$C$12,D44=policy_name_clustering!$A$13,policy_name_clustering!$C$13,D44=policy_name_clustering!$A$14,policy_name_clustering!$C$14,D44=policy_name_clustering!$A$15,policy_name_clustering!$C$15,D44=policy_name_clustering!$A$16,policy_name_clustering!$C$16,D44="-","",D44=policy_name_clustering!$A$4,policy_name_clustering!$C$4)} | G44: =wind_cump_cap!C46 -> 14 | H44: =estimated_capacity!C44 -> 388.70055 | I44: {=_xlfn.IFS(D44= ""," ",D44<> " ",F44*(G44/H44))} -> 0 | J44: {=_xlfn.IFS(D44= ""," ",D44<> " ",(H44-F44)*(G44/H44))} -> 14 | K44: {=IF(ISNUMBER(H44),_xlfn.IFS(D44= ""," ",D44<> " ",F44*(G44/H44)),"")} -> 0
A45: BEL | B45: 2001 | D45: - | E45: {=_xlfn.IFS(D45=policy_name_clustering!$A$2,policy_name_clustering!$C$2,D45=policy_name_clustering!$A$3,policy_name_clustering!$C$3,D45=policy_name_clustering!$A$5,policy_name_clustering!$C$5,D45=policy_name_clustering!$A$6,policy_name_clustering!$C$6,D45=policy_name_clustering!$A$7,policy_name_clustering!$C$7,D45=policy_name_clustering!$A$8,policy_name_clustering!$C$8,D45=policy_name_clustering!$A$9,policy_name_clustering!$C$9,D45=policy_name_clustering!$A$10,policy_name_clustering!$C$10,D45=policy_name_clustering!$A$11,policy_name_clustering!$C$11,D45=policy_name_clustering!$A$12,policy_name_clustering!$C$12,D45=policy_name_clustering!$A$13,policy_name_clustering!$C$13,D45=policy_name_clustering!$A$14,policy_name_clustering!$C$14,D45=policy_name_clustering!$A$15,policy_name_clustering!$C$15,D45=policy_name_clustering!$A$16,policy_name_clustering!$C$16,D45="-","",D45=policy_name_clustering!$A$4,policy_name_clustering!$C$4)} | G45: =wind_cump_cap!C47 -> 26 | H45: =estimated_capacity!C45 -> 483.22013 | I45: {=_xlfn.IFS(D45= ""," ",D45<> " ",F45*(G45/H45))} -> 0 | J45: {=_xlfn.IFS(D45= ""," ",D45<> " ",(H45-F45)*(G45/H45))} -> 26 | K45: {=IF(ISNUMBER(H45),_xlfn.IFS(D45= ""," ",D45<> " ",F45*(G45/H45)),"")} -> 0
A46: BEL | B46: 2002 | D46: - | E46: {=_xlfn.IFS(D46=policy_name_clustering!$A$2,policy_name_clustering!$C$2,D46=policy_name_clustering!$A$3,policy_name_clustering!$C$3,D46=policy_name_clustering!$A$5,policy_name_clustering!$C$5,D46=policy_name_clustering!$A$6,policy_name_clustering!$C$6,D46=policy_name_clustering!$A$7,policy_name_clustering!$C$7,D46=policy_name_clustering!$A$8,policy_name_clustering!$C$8,D46=policy_name_clustering!$A$9,policy_name_clustering!$C$9,D46=policy_name_clustering!$A$10,policy_name_clustering!$C$10,D46=policy_name_clustering!$A$11,policy_name_clustering!$C$11,D46=policy_name_clustering!$A$12,policy_name_clustering!$C$12,D46=policy_name_clustering!$A$13,policy_name_clustering!$C$13,D46=policy_name_clustering!$A$14,policy_name_clustering!$C$14,D46=policy_name_clustering!$A$15,policy_name_clustering!$C$15,D46=policy_name_clustering!$A$16,policy_name_clustering!$C$16,D46="-","",D46=policy_name_clustering!$A$4,policy_name_clustering!$C$4)} | G46: =wind_cump_cap!C48 -> 31 | H46: =estimated_capacity!C46 -> 580.25811 | I46: {=_xlfn.IFS(D46= ""," ",D46<> " ",F46*(G46/H46))} -> 0 | J46: {=_xlfn.IFS(D46= ""," ",D46<> " ",(H46-F46)*(G46/H46))} -> 31 | K46: {=IF(ISNUMBER(H46),_xlfn.IFS(D46= ""," ",D46<> " ",F46*(G46/H46)),"")} -> 0
... A66: BEL | B66: 2022 | D66: - | E66: {=_xlfn.IFS(D66=policy_name_clustering!$A$2,policy_name_clustering!$C$2,D66=policy_name_clustering!$A$3,policy_name_clustering!$C$3,D66=policy_name_clustering!$A$5,policy_name_clustering!$C$5,D66=policy_name_clustering!$A$6,policy_name_clustering!$C$6,D66=policy_name_clustering!$A$7,policy_name_clustering!$C$7,D66=policy_name_clustering!$A$8,policy_name_clustering!$C$8,D66=policy_name_clustering!$A$9,policy_name_clustering!$C$9,D66=policy_name_clustering!$A$10,policy_name_clustering!$C$10,D66=policy_name_clustering!$A$11,policy_name_clustering!$C$11,D66=policy_name_clustering!$A$12,policy_name_clustering!$C$12,D66=policy_name_clustering!$A$13,policy_name_clustering!$C$13,D66=policy_name_clustering!$A$14,policy_name_clustering!$C$14,D66=policy_name_clustering!$A$15,policy_name_clustering!$C$15,D66=policy_name_clustering!$A$16,policy_name_clustering!$C$16,D66="-","",D66=policy_name_clustering!$A$4,policy_name_clustering!$C$4)} | G66: =wind_cump_cap!C68 -> 5303.4 | H66: =estimated_capacity!C66 -> 4287.8509 | I66: {=_xlfn.IFS(D66= ""," ",D66<> " ",F66*(G66/H66))} -> 0 | J66: {=_xlfn.IFS(D66= ""," ",D66<> " ",(H66-F66)*(G66/H66))} -> 5303.4 | K66: {=IF(ISNUMBER(H66),_xlfn.IFS(D66= ""," ",D66<> " ",F66*(G66/H66)),"")} -> 0
A67: BEL | B67: 2023 | D67: - | E67: {=_xlfn.IFS(D67=policy_name_clustering!$A$2,policy_name_clustering!$C$2,D67=policy_name_clustering!$A$3,policy_name_clustering!$C$3,D67=policy_name_clustering!$A$5,policy_name_clustering!$C$5,D67=policy_name_clustering!$A$6,policy_name_clustering!$C$6,D67=policy_name_clustering!$A$7,policy_name_clustering!$C$7,D67=policy_name_clustering!$A$8,policy_name_clustering!$C$8,D67=policy_name_clustering!$A$9,policy_name_clustering!$C$9,D67=policy_name_clustering!$A$10,policy_name_clustering!$C$10,D67=policy_name_clustering!$A$11,policy_name_clustering!$C$11,D67=policy_name_clustering!$A$12,policy_name_clustering!$C$12,D67=policy_name_clustering!$A$13,policy_name_clustering!$C$13,D67=policy_name_clustering!$A$14,policy_name_clustering!$C$14,D67=policy_name_clustering!$A$15,policy_name_clustering!$C$15,D67=policy_name_clustering!$A$16,policy_name_clustering!$C$16,D67="-","",D67=policy_name_clustering!$A$4,policy_name_clustering!$C$4)} | G67: =wind_cump_cap!C69 -> 5454.1 | H67: =estimated_capacity!C67 -> 4690.244 | I67: {=_xlfn.IFS(D67= ""," ",D67<> " ",F67*(G67/H67))} -> 0 | J67: {=_xlfn.IFS(D67= ""," ",D67<> " ",(H67-F67)*(G67/H67))} -> 5454.1 | K67: {=IF(ISNUMBER(H67),_xlfn.IFS(D67= ""," ",D67<> " ",F67*(G67/H67)),"")} -> 0 | N67: =SUM(G34,G67,G105,G138,G184,G217,G255,G346,G315,G379,G420,G442,G475,G503,G536,G589)-SUM(H589,H536,H503,H475,H442,H420,H379,H346,H315,H255,H217,H184,H138,H105,H67,H34) -> 1191.1217
A68: DEU | B68: 1991 | D68: - | E68: {=_xlfn.IFS(D68=policy_name_clustering!$A$2,policy_name_clustering!$C$2,D68=policy_name_clustering!$A$3,policy_name_clustering!$C$3,D68=policy_name_clustering!$A$5,policy_name_clustering!$C$5,D68=policy_name_clustering!$A$6,policy_name_clustering!$C$6,D68=policy_name_clustering!$A$7,policy_name_clustering!$C$7,D68=policy_name_clustering!$A$8,policy_name_clustering!$C$8,D68=policy_name_clustering!$A$9,policy_name_clustering!$C$9,D68=policy_name_clustering!$A$10,policy_name_clustering!$C$10,D68=policy_name_clustering!$A$11,policy_name_clustering!$C$11,D68=policy_name_clustering!$A$12,policy_name_clustering!$C$12,D68=policy_name_clustering!$A$13,policy_name_clustering!$C$13,D68=policy_name_clustering!$A$14,policy_name_clustering!$C$14,D68=policy_name_clustering!$A$15,policy_name_clustering!$C$15,D68=policy_name_clustering!$A$16,policy_name_clustering!$C$16,D68="-","",D68=policy_name_clustering!$A$4,policy_name_clustering!$C$4)} | G68: =wind_cump_cap!C71 -> 110 | H68: =estimated_capacity!C68 -> 88.425538 | I68: {=_xlfn.IFS(D68= ""," ",D68<> " ",F68*(G68/H68))} -> 0 | J68: {=_xlfn.IFS(D68= ""," ",D68<> " ",(H68-F68)*(G68/H68))} -> 110 | K68: {=IF(ISNUMBER(H68),_xlfn.IFS(D68= ""," ",D68<> " ",F68*(G68/H68)),"")} -> 0
A69: DEU | B69: 1992 | D69: - | E69: {=_xlfn.IFS(D69=policy_name_clustering!$A$2,policy_name_clustering!$C$2,D69=policy_name_clustering!$A$3,policy_name_clustering!$C$3,D69=policy_name_clustering!$A$5,policy_name_clustering!$C$5,D69=policy_name_clustering!$A$6,policy_name_clustering!$C$6,D69=policy_name_clustering!$A$7,policy_name_clustering!$C$7,D69=policy_name_clustering!$A$8,policy_name_clustering!$C$8,D69=policy_name_clustering!$A$9,policy_name_clustering!$C$9,D69=policy_name_clustering!$A$10,policy_name_clustering!$C$10,D69=policy_name_clustering!$A$11,policy_name_clustering!$C$11,D69=policy_name_clustering!$A$12,policy_name_clustering!$C$12,D69=policy_name_clustering!$A$13,policy_name_clustering!$C$13,D69=policy_name_clustering!$A$14,policy_name_clustering!$C$14,D69=policy_name_clustering!$A$15,policy_name_clustering!$C$15,D69=policy_name_clustering!$A$16,policy_name_clustering!$C$16,D69="-","",D69=policy_name_clustering!$A$4,policy_name_clustering!$C$4)} | G69: =wind_cump_cap!C72 -> 183 | H69: =estimated_capacity!C69 -> 182.77566 | I69: {=_xlfn.IFS(D69= ""," ",D69<> " ",F69*(G69/H69))} -> 0 | J69: {=_xlfn.IFS(D69= ""," ",D69<> " ",(H69-F69)*(G69/H69))} -> 183 | K69: {=IF(ISNUMBER(H69),_xlfn.IFS(D69= ""," ",D69<> " ",F69*(G69/H69)),"")} -> 0
A70: DEU | B70: 1993 | C70: FiT intro -1991 | D70: FiT | E70: {=_xlfn.IFS(D70=policy_name_clustering!$A$2,policy_name_clustering!$C$2,D70=policy_name_clustering!$A$3,policy_name_clustering!$C$3,D70=policy_name_clustering!$A$5,policy_name_clustering!$C$5,D70=policy_name_clustering!$A$6,policy_name_clustering!$C$6,D70=policy_name_clustering!$A$7,policy_name_clustering!$C$7,D70=policy_name_clustering!$A$8,policy_name_clustering!$C$8,D70=policy_name_clustering!$A$9,policy_name_clustering!$C$9,D70=policy_name_clustering!$A$10,policy_name_clustering!$C$10,D70=policy_name_clustering!$A$11,policy_name_clustering!$C$11,D70=policy_name_clustering!$A$12,policy_name_clustering!$C$12,D70=policy_name_clustering!$A$13,policy_name_clustering!$C$13,D70=policy_name_clustering!$A$14,policy_name_clustering!$C$14,D70=policy_name_clustering!$A$15,policy_name_clustering!$C$15,D70=policy_name_clustering!$A$16,policy_name_clustering!$C$16,D70="-","",D70=policy_name_clustering!$A$4,policy_name_clustering!$C$4)} -> FiT/FiP-based | F70: =policy_contributions_cum!F2 -> 51.921175 | G70: =wind_cump_cap!C73 -> 334 | H70: =estimated_capacity!C70 -> 343.94999 | I70: {=_xlfn.IFS(D70= ""," ",D70<> " ",F70*(G70/H70))} -> 50.419168 | J70: {=_xlfn.IFS(D70= ""," ",D70<> " ",(H70-F70)*(G70/H70))} -> 283.58083 | K70: {=IF(ISNUMBER(H70),_xlfn.IFS(D70= ""," ",D70<> " ",F70*(G70/H70)),"")} -> 50.419168
A71: DEU | B71: 1994 | C71: FiT intro -1991 | D71: FiT | E71: {=_xlfn.IFS(D71=policy_name_clustering!$A$2,policy_name_clustering!$C$2,D71=policy_name_clustering!$A$3,policy_name_clustering!$C$3,D71=policy_name_clustering!$A$5,policy_name_clustering!$C$5,D71=policy_name_clustering!$A$6,policy_name_clustering!$C$6,D71=policy_name_clustering!$A$7,policy_name_clustering!$C$7,D71=policy_name_clustering!$A$8,policy_name_clustering!$C$8,D71=policy_name_clustering!$A$9,policy_name_clustering!$C$9,D71=policy_name_clustering!$A$10,policy_name_clustering!$C$10,D71=policy_name_clustering!$A$11,policy_name_clustering!$C$11,D71=policy_name_clustering!$A$12,policy_name_clustering!$C$12,D71=policy_name_clustering!$A$13,policy_name_clustering!$C$13,D71=policy_name_clustering!$A$14,policy_name_clustering!$C$14,D71=policy_name_clustering!$A$15,policy_name_clustering!$C$15,D71=policy_name_clustering!$A$16,policy_name_clustering!$C$16,D71="-","",D71=policy_name_clustering!$A$4,policy_name_clustering!$C$4)} -> FiT/FiP-based | F71: =policy_contributions_cum!F3 -> 172.94021 | G71: =wind_cump_cap!C74 -> 643 | H71: =estimated_capacity!C71 -> 582.1443 | I71: {=_xlfn.IFS(D71= ""," ",D71<> " ",F71*(G71/H71))} -> 191.01889 | J71: {=_xlfn.IFS(D71= ""," ",D71<> " ",(H71-F71)*(G71/H71))} -> 451.98111 | K71: {=IF(ISNUMBER(H71),_xlfn.IFS(D71= ""," ",D71<> " ",F71*(G71/H71)),"")} -> 191.01889
A72: DEU | B72: 1995 | C72: FiT intro -1991 | D72: FiT | E72: {=_xlfn.IFS(D72=policy_name_clustering!$A$2,policy_name_clustering!$C$2,D72=policy_name_clustering!$A$3,policy_name_clustering!$C$3,D72=policy_name_clustering!$A$5,policy_name_clustering!$C$5,D72=policy_name_clustering!$A$6,policy_name_clustering!$C$6,D72=policy_name_clustering!$A$7,policy_name_clustering!$C$7,D72=policy_name_clustering!$A$8,policy_name_clustering!$C$8,D72=policy_name_clustering!$A$9,policy_name_clustering!$C$9,D72=policy_name_clustering!$A$10,policy_name_clustering!$C$10,D72=policy_name_clustering!$A$11,policy_name_clustering!$C$11,D72=policy_name_clustering!$A$12,policy_name_clustering!$C$12,D72=policy_name_clustering!$A$13,policy_name_clustering!$C$13,D72=policy_name_clustering!$A$14,policy_name_clustering!$C$14,D72=policy_name_clustering!$A$15,policy_name_clustering!$C$15,D72=policy_name_clustering!$A$16,policy_name_clustering!$C$16,D72="-","",D72=policy_name_clustering!$A$4,policy_name_clustering!$C$4)} -> FiT/FiP-based | F72: =policy_contributions_cum!F4 -> 401.54788 | G72: =wind_cump_cap!C75 -> 1137 | H72: =estimated_capacity!C72 -> 953.45563 | I72: {=_xlfn.IFS(D72= ""," ",D72<> " ",F72*(G72/H72))} -> 478.84761 | J72: {=_xlfn.IFS(D72= ""," ",D72<> " ",(H72-F72)*(G72/H72))} -> 658.15239 | K72: {=IF(ISNUMBER(H72),_xlfn.IFS(D72= ""," ",D72<> " ",F72*(G72/H72)),"")} -> 478.84761
A73: DEU | B73: 1996 | C73: FiT intro -1991 | D73: FiT | E73: {=_xlfn.IFS(D73=policy_name_clustering!$A$2,policy_name_clustering!$C$2,D73=policy_name_clustering!$A$3,policy_name_clustering!$C$3,D73=policy_name_clustering!$A$5,policy_name_clustering!$C$5,D73=policy_name_clustering!$A$6,policy_name_clustering!$C$6,D73=policy_name_clustering!$A$7,policy_name_clustering!$C$7,D73=policy_name_clustering!$A$8,policy_name_clustering!$C$8,D73=policy_name_clustering!$A$9,policy_name_clustering!$C$9,D73=policy_name_clustering!$A$10,policy_name_clustering!$C$10,D73=policy_name_clustering!$A$11,policy_name_clustering!$C$11,D73=policy_name_clustering!$A$12,policy_name_clustering!$C$12,D73=policy_name_clustering!$A$13,policy_name_clustering!$C$13,D73=policy_name_clustering!$A$14,policy_name_clustering!$C$14,D73=policy_name_clustering!$A$15,policy_name_clustering!$C$15,D73=policy_name_clustering!$A$16,policy_name_clustering!$C$16,D73="-","",D73=policy_name_clustering!$A$4,policy_name_clustering!$C$4)} -> FiT/FiP-based | F73: =policy_contributions_cum!F5 -> 772.96717 | G73: =wind_cump_cap!C76 -> 1564 | H73: =estimated_capacity!C73 -> 1486.2066 | I73: {=_xlfn.IFS(D73= ""," ",D73<> " ",F73*(G73/H73))} -> 813.42707 | J73: {=_xlfn.IFS(D73= ""," ",D73<> " ",(H73-F73)*(G73/H73))} -> 750.57293 | K73: {=IF(ISNUMBER(H73),_xlfn.IFS(D73= ""," ",D73<> " ",F73*(G73/H73)),"")} -> 813.42707
A74: DEU | B74: 1997 | C74: FiT intro -1991 | D74: FiT | E74: {=_xlfn.IFS(D74=policy_name_clustering!$A$2,policy_name_clustering!$C$2,D74=policy_name_clustering!$A$3,policy_name_clustering!$C$3,D74=policy_name_clustering!$A$5,policy_name_clustering!$C$5,D74=policy_name_clustering!$A$6,policy_name_clustering!$C$6,D74=policy_name_clustering!$A$7,policy_name_clustering!$C$7,D74=policy_name_clustering!$A$8,policy_name_clustering!$C$8,D74=policy_name_clustering!$A$9,policy_name_clustering!$C$9,D74=policy_name_clustering!$A$10,policy_name_clustering!$C$10,D74=policy_name_clustering!$A$11,policy_name_clustering!$C$11,D74=policy_name_clustering!$A$12,policy_name_clustering!$C$12,D74=policy_name_clustering!$A$13,policy_name_clustering!$C$13,D74=policy_name_clustering!$A$14,policy_name_clustering!$C$14,D74=policy_name_clustering!$A$15,policy_name_clustering!$C$15,D74=policy_name_clustering!$A$16,policy_name_clustering!$C$16,D74="-","",D74=policy_name_clustering!$A$4,policy_name_clustering!$C$4)} -> FiT/FiP-based | F74: =policy_contributions_cum!F6 -> 1352.5843 | G74: =wind_cump_cap!C77 -> 1966 | H74: =estimated_capacity!C74 -> 2253.023 | I74: {=_xlfn.IFS(D74= ""," ",D74<> " ",F74*(G74/H74))} -> 1180.2723 | J74: {=_xlfn.IFS(D74= ""," ",D74<> " ",(H74-F74)*(G74/H74))} -> 785.7277 | K74: {=IF(ISNUMBER(H74),_xlfn.IFS(D74= ""," ",D74<> " ",F74*(G74/H74)),"")} -> 1180.2723
A75: DEU | B75: 1998 | C75: FiT intro -1991 | D75: FiT | E75: {=_xlfn.IFS(D75=policy_name_clustering!$A$2,policy_name_clustering!$C$2,D75=policy_name_clustering!$A$3,policy_name_clustering!$C$3,D75=policy_name_clustering!$A$5,policy_name_clustering!$C$5,D75=policy_name_clustering!$A$6,policy_name_clustering!$C$6,D75=policy_name_clustering!$A$7,policy_name_clustering!$C$7,D75=policy_name_clustering!$A$8,policy_name_clustering!$C$8,D75=policy_name_clustering!$A$9,policy_name_clustering!$C$9,D75=policy_name_clustering!$A$10,policy_name_clustering!$C$10,D75=policy_name_clustering!$A$11,policy_name_clustering!$C$11,D75=policy_name_clustering!$A$12,policy_name_clustering!$C$12,D75=policy_name_clustering!$A$13,policy_name_clustering!$C$13,D75=policy_name_clustering!$A$14,policy_name_clustering!$C$14,D75=policy_name_clustering!$A$15,policy_name_clustering!$C$15,D75=policy_name_clustering!$A$16,policy_name_clustering!$C$16,D75="-","",D75=policy_name_clustering!$A$4,policy_name_clustering!$C$4)} -> FiT/FiP-based | F75: =policy_contributions_cum!F7 -> 2165.6656 | G75: =wind_cump_cap!C78 -> 2672 | H75: =estimated_capacity!C75 -> 3260.4103 | I75: {=_xlfn.IFS(D75= ""," ",D75<> " ",F75*(G75/H75))} -> 1774.8252 | J75: {=_xlfn.IFS(D75= ""," ",D75<> " ",(H75-F75)*(G75/H75))} -> 897.1748 | K75: {=IF(ISNUMBER(H75),_xlfn.IFS(D75= ""," ",D75<> " ",F75*(G75/H75)),"")} -> 1774.8252
A76: DEU | B76: 1999 | C76: FiT intro -1991 | D76: FiT | E76: {=_xlfn.IFS(D76=policy_name_clustering!$A$2,policy_name_clustering!$C$2,D76=policy_name_clustering!$A$3,policy_name_clustering!$C$3,D76=policy_name_clustering!$A$5,policy_name_clustering!$C$5,D76=policy_name_clustering!$A$6,policy_name_clustering!$C$6,D76=policy_name_clustering!$A$7,policy_name_clustering!$C$7,D76=policy_name_clustering!$A$8,policy_name_clustering!$C$8,D76=policy_name_clustering!$A$9,policy_name_clustering!$C$9,D76=policy_name_clustering!$A$10,policy_name_clustering!$C$10,D76=policy_name_clustering!$A$11,policy_name_clustering!$C$11,D76=policy_name_clustering!$A$12,policy_name_clustering!$C$12,D76=policy_name_clustering!$A$13,policy_name_clustering!$C$13,D76=policy_name_clustering!$A$14,policy_name_clustering!$C$14,D76=policy_name_clustering!$A$15,policy_name_clustering!$C$15,D76=policy_name_clustering!$A$16,policy_name_clustering!$C$16,D76="-","",D76=policy_name_clustering!$A$4,policy_name_clustering!$C$4)} -> FiT/FiP-based | F76: =policy_contributions_cum!F8 -> 3347.1257 | G76: =wind_cump_cap!C79 -> 4138 | H76: =estimated_capacity!C76 -> 4662.0933 | I76: {=_xlfn.IFS(D76= ""," ",D76<> " ",F76*(G76/H76))} -> 2970.8556 | J76: {=_xlfn.IFS(D76= ""," ",D76<> " ",(H76-F76)*(G76/H76))} -> 1167.1444 | K76: {=IF(ISNUMBER(H76),_xlfn.IFS(D76= ""," ",D76<> " ",F76*(G76/H76)),"")} -> 2970.8556
A77: DEU | B77: 2000 | C77: FiT intro -1991 | D77: FiT | E77: {=_xlfn.IFS(D77=policy_name_clustering!$A$2,policy_name_clustering!$C$2,D77=policy_name_clustering!$A$3,policy_name_clustering!$C$3,D77=policy_name_clustering!$A$5,policy_name_clustering!$C$5,D77=policy_name_clustering!$A$6,policy_name_clustering!$C$6,D77=policy_name_clustering!$A$7,policy_name_clustering!$C$7,D77=policy_name_clustering!$A$8,policy_name_clustering!$C$8,D77=policy_name_clustering!$A$9,policy_name_clustering!$C$9,D77=policy_name_clustering!$A$10,policy_name_clustering!$C$10,D77=policy_name_clustering!$A$11,policy_name_clustering!$C$11,D77=policy_name_clustering!$A$12,policy_name_clustering!$C$12,D77=policy_name_clustering!$A$13,policy_name_clustering!$C$13,D77=policy_name_clustering!$A$14,policy_name_clustering!$C$14,D77=policy_name_clustering!$A$15,policy_name_clustering!$C$15,D77=policy_name_clustering!$A$16,policy_name_clustering!$C$16,D77="-","",D77=policy_name_clustering!$A$4,policy_name_clustering!$C$4)} -> FiT/FiP-based | F77: =policy_contributions_cum!F9 -> 4917.8922 | G77: =wind_cump_cap!C80 -> 6095 | H77: =estimated_capacity!C77 -> 6457.0135 | I77: {=_xlfn.IFS(D77= ""," ",D77<> " ",F77*(G77/H77))} -> 4642.1697 | J77: {=_xlfn.IFS(D77= ""," ",D77<> " ",(H77-F77)*(G77/H77))} -> 1452.8303 | K77: {=IF(ISNUMBER(H77),_xlfn.IFS(D77= ""," ",D77<> " ",F77*(G77/H77)),"")} -> 4642.1697
A78: DEU | B78: 2001 | C78: FiT intro -1991 | D78: FiT | E78: {=_xlfn.IFS(D78=policy_name_clustering!$A$2,policy_name_clustering!$C$2,D78=policy_name_clustering!$A$3,policy_name_clustering!$C$3,D78=policy_name_clustering!$A$5,policy_name_clustering!$C$5,D78=policy_name_clustering!$A$6,policy_name_clustering!$C$6,D78=policy_name_clustering!$A$7,policy_name_clustering!$C$7,D78=policy_name_clustering!$A$8,policy_name_clustering!$C$8,D78=policy_name_clustering!$A$9,policy_name_clustering!$C$9,D78=policy_name_clustering!$A$10,policy_name_clustering!$C$10,D78=policy_name_clustering!$A$11,policy_name_clustering!$C$11,D78=policy_name_clustering!$A$12,policy_name_clustering!$C$12,D78=policy_name_clustering!$A$13,policy_name_clustering!$C$13,D78=policy_name_clustering!$A$14,policy_name_clustering!$C$14,D78=policy_name_clustering!$A$15,policy_name_clustering!$C$15,D78=policy_name_clustering!$A$16,policy_name_clustering!$C$16,D78="-","",D78=policy_name_clustering!$A$4,policy_name_clustering!$C$4)} -> FiT/FiP-based | F78: =policy_contributions_cum!F10 -> 7144.8939 | G78: =wind_cump_cap!C81 -> 8754 | H78: =estimated_capacity!C78 -> 8938.369 | I78: {=_xlfn.IFS(D78= ""," ",D78<> " ",F78*(G78/H78))} -> 6997.5183 | J78: {=_xlfn.IFS(D78= ""," ",D78<> " ",(H78-F78)*(G78/H78))} -> 1756.4817 | K78: {=IF(ISNUMBER(H78),_xlfn.IFS(D78= ""," ",D78<> " ",F78*(G78/H78)),"")} -> 6997.5183
A79: DEU | B79: 2002 | C79: negative break here: FiT degression intro - 2000 | D79: FiT | E79: {=_xlfn.IFS(D79=policy_name_clustering!$A$2,policy_name_clustering!$C$2,D79=policy_name_clustering!$A$3,policy_name_clustering!$C$3,D79=policy_name_clustering!$A$5,policy_name_clustering!$C$5,D79=policy_name_clustering!$A$6,policy_name_clustering!$C$6,D79=policy_name_clustering!$A$7,policy_name_clustering!$C$7,D79=policy_name_clustering!$A$8,policy_name_clustering!$C$8,D79=policy_name_clustering!$A$9,policy_name_clustering!$C$9,D79=policy_name_clustering!$A$10,policy_name_clustering!$C$10,D79=policy_name_clustering!$A$11,policy_name_clustering!$C$11,D79=policy_name_clustering!$A$12,policy_name_clustering!$C$12,D79=policy_name_clustering!$A$13,policy_name_clustering!$C$13,D79=policy_name_clustering!$A$14,policy_name_clustering!$C$14,D79=policy_name_clustering!$A$15,policy_name_clustering!$C$15,D79=policy_name_clustering!$A$16,policy_name_clustering!$C$16,D79="-","",D79=policy_name_clustering!$A$4,policy_name_clustering!$C$4)} -> FiT/FiP-based | F79: =policy_contributions_cum!F11 -> 9401.1321 | G79: =wind_cump_cap!C82 -> 12001 | H79: =estimated_capacity!C79 -> 11373.513 | I79: {=_xlfn.IFS(D79= ""," ",D79<> " ",F79*(G79/H79))} -> 9919.8015 | J79: {=_xlfn.IFS(D79= ""," ",D79<> " ",(H79-F79)*(G79/H79))} -> 2081.1985 | K79: {=IF(ISNUMBER(H79),_xlfn.IFS(D79= ""," ",D79<> " ",F79*(G79/H79)),"")} -> 9919.8015
...

Sheet cumulative_effects
A1: policy instrument | B1: error-adjusted Cumulative policy instrument effect in GW
A2: FiT | B2: =SUMIFS(effect_quant_by_period!$I$2:$I$589,effect_quant_by_period!$D$2:$D$589,A2,effect_quant_by_period!$B$2:$B$589,estimated_capacity!$K$1)/1000 -> 85.849186
A3: FiT prolonged, FiT support duration increased | B3: =SUMIFS(effect_quant_by_period!$I$2:$I$589,effect_quant_by_period!$D$2:$D$589,A3,effect_quant_by_period!$B$2:$B$589,estimated_capacity!$K$1)/1000 -> 12.50677
A4: FiP | B4: =SUMIFS(effect_quant_by_period!$I$2:$I$589,effect_quant_by_period!$D$2:$D$589,A4,effect_quant_by_period!$B$2:$B$589,estimated_capacity!$K$1)/1000 -> 6.6995896
A5: Tax incentive, Subsidy, TGC | B5: =SUMIFS(effect_quant_by_period!$I$2:$I$589,effect_quant_by_period!$D$2:$D$589,A5,effect_quant_by_period!$B$2:$B$589,estimated_capacity!$K$1)/1000 -> 0.42229176
A6: Tax incentive, TGC | B6: =SUMIFS(effect_quant_by_period!$I$2:$I$589,effect_quant_by_period!$D$2:$D$589,A6,effect_quant_by_period!$B$2:$B$589,estimated_capacity!$K$1)/1000 -> 16.953336
A7: TGC | B7: =SUMIFS(effect_quant_by_period!$I$2:$I$589,effect_quant_by_period!$D$2:$D$589,A7,effect_quant_by_period!$B$2:$B$589,estimated_capacity!$K$1)/1000 -> 9.5113122
A8: Tax incentive, TGC level increase | B8: =SUMIFS(effect_quant_by_period!$I$2:$I$589,effect_quant_by_period!$D$2:$D$589,A8,effect_quant_by_period!$B$2:$B$589,estimated_capacity!$K$1)/1000 -> 7.5580639
A9: TGC aim increase, Tax incentive | B9: =SUMIFS(effect_quant_by_period!$I$2:$I$589,effect_quant_by_period!$D$2:$D$589,A9,effect_quant_by_period!$B$2:$B$589,estimated_capacity!$K$1)/1000 -> 8.4137234
A10: Tax incentive | B10: =SUMIFS(effect_quant_by_period!$I$2:$I$589,effect_quant_by_period!$D$2:$D$589,A10,effect_quant_by_period!$B$2:$B$589,estimated_capacity!$K$1)/1000 -> 3.9040364
A11: Tax incentive increase, TGC aim increase, Tender | B11: =SUMIFS(effect_quant_by_period!$I$2:$I$589,effect_quant_by_period!$D$2:$D$589,A11,effect_quant_by_period!$B$2:$B$589,estimated_capacity!$K$1)/1000 -> 4.6048161
A12: Subsidy prolonged, Tax incentive level increased | B12: =SUMIFS(effect_quant_by_period!$I$2:$I$589,effect_quant_by_period!$D$2:$D$589,A12,effect_quant_by_period!$B$2:$B$589,estimated_capacity!$K$1)/1000 -> 2.2156931
A13: Tender | B13: =SUMIFS(effect_quant_by_period!$I$2:$I$589,effect_quant_by_period!$D$2:$D$589,A13,effect_quant_by_period!$B$2:$B$589,estimated_capacity!$K$1)/1000 -> 25.08644
... A16: Subsidy prolonged | B16: =SUMIFS(effect_quant_by_period!$I$2:$I$589,effect_quant_by_period!$D$2:$D$589,A16,effect_quant_by_period!$B$2:$B$589,estimated_capacity!$K$1)/1000 -> 1.1515816
A17: Total policy effect | B17: =SUM(B2:B16) -> 197.6152 | C17: =SUMIFS(effect_quant_by_period!$J$2:$J$589,effect_quant_by_period!$B$2:$B$589,2023)/1000 -> 45.272322 | D17: =estimated_capacity!G2-B17 -> 44.0812
A18: Non-policy factors | B18: =SUMIFS(effect_quant_by_period!$J$2:$J$589,effect_quant_by_period!$B$2:$B$589,2023)/1000 -> 45.272322 | C18: =(estimated_capacity!G2-B17)-C17 -> -1.1911217 | D18: difference as model estimated cumulative capacity is not error adjusted!
A19: Policy effect share | B19: =B17/SUM(B17:B18) -> 0.81360787
A21: policy instrument | B21: error-adjusted Cumulative policy instrument effect in GW
A22: FiT/FiP-based | B22: =SUM(B2:B4) -> 105.05555
A23: Tender-based | B23: =SUM(B13) -> 25.08644
A24: TGC-based | B24: =SUM(B7) -> 9.5113122
A25: Tax-based | B25: =SUM(B10) -> 3.9040364
A26: Policy mix | B26: =SUM(B14,B11,B6,B5,B9,B8,B12,B15) -> 52.906285
A27: Other single instrument | B27: =SUM(B16) -> 1.1515816
A28: Total policy effect | B28: =B17 -> 197.6152
A29: Non-policy factors | B29: =B18 -> 45.272322

Sheet policy_contributions_cum
A1: id | B1: time | C1: policy | D1: effect_mw | E1: benchmark_mw | F1: cumulative_effect_mw
A2: DEU | B2: 1993 | C2: effect_tisDEU.1993 | D2: 51.921175 | E2: 161.17433 | F2: 51.921175
A3: DEU | B3: 1994 | C3: effect_tisDEU.1993 | D3: 121.01904 | E3: 238.19431 | F3: 172.94021
A4: DEU | B4: 1995 | C4: effect_tisDEU.1993 | D4: 228.60767 | E4: 371.31132 | F4: 401.54788
A5: DEU | B5: 1996 | C5: effect_tisDEU.1993 | D5: 371.41928 | E5: 532.75093 | F5: 772.96717
A6: DEU | B6: 1997 | C6: effect_tisDEU.1993 | D6: 579.6171 | E6: 766.81647 | F6: 1352.5843
A7: DEU | B7: 1998 | C7: effect_tisDEU.1993 | D7: 813.0813 | E7: 1007.3873 | F7: 2165.6656
A8: DEU | B8: 1999 | C8: effect_tisDEU.1993 | D8: 1181.4601 | E8: 1401.683 | F8: 3347.1257
A9: DEU | B9: 2000 | C9: effect_tisDEU.1993 | D9: 1570.7665 | E9: 1794.9202 | F9: 4917.8922
A10: DEU | B10: 2001 | C10: effect_tisDEU.1993 | D10: 2227.0017 | E10: 2481.3555 | F10: 7144.8939
A11: DEU | B11: 2002 | C11: effect_tisDEU.1993 | D11: 2256.2382 | E11: 2435.1435 | F11: 9401.1321
A12: DEU | B12: 2003 | C12: effect_tisDEU.1993 | D12: 2458.1153 | E12: 2595.8467 | F12: 11859.247
A13: DEU | B13: 2004 | C13: effect_tisDEU.1993 | D13: 2406.7327 | E13: 2489.6182 | F13: 14265.98
... A208: SWE | B208: 2023 | C208: effect_fesisSWE.2008 | D208: 1118.9349 | E208: 1503.0466 | F208: 11223.456

Sheet wind_cump_cap
A1: year | B1: country | C1: wind.cap | E1: Eur_cum_cap_wind_GW | H1: end sample year | I1: 2023
A2: 1990 | B2: AUT | C2: 0 | E2: =SUMIF($A$2:$A$523,$I$1,$C$2:$C$523)/1000 -> 242.88752
A3: 1991 | B3: AUT | C3: 0
A4: 1992 | B4: AUT | C4: 0
A5: 1993 | B5: AUT | C5: 1
A6: 1994 | B6: AUT | C6: 1
A7: 1995 | B7: AUT | C7: 1
A8: 1996 | B8: AUT | C8: 3
A9: 1997 | B9: AUT | C9: 15
A10: 1998 | B10: AUT | C10: 34
A11: 1999 | B11: AUT | C11: 38
A12: 2000 | B12: AUT | C12: 50
A13: 2001 | B13: AUT | C13: 67
A14: 2002 | B14: AUT | C14: 109
... A523: 2023 | B523: SWE | C523: 16224

Sheet estimated_capacity
A1: id | B1: time | C1: estimated_cumulative_wind_cap_MW | G1: Eur_estimated_cum_cap_GW | J1: end sample year | K1: 2023
A2: AUT | B2: 1991 | C2: -8.2265578 | G2: =SUMIF($B$2:$B$507,$K$1,$C$2:$C$507)/1000 -> 241.6964
A3: AUT | B3: 1992 | C3: -12.430992
A4: AUT | B4: 1993 | C4: -10.517072
A5: AUT | B5: 1994 | C5: -4.4677335
A6: AUT | B6: 1995 | C6: 13.625984
A7: AUT | B7: 1996 | C7: 41.36612
A8: AUT | B8: 1997 | C8: 81.797647
A9: AUT | B9: 1998 | C9: 125.66332
A10: AUT | B10: 1999 | C10: 181.79522
A11: AUT | B11: 2000 | C11: 239.55534
A12: AUT | B12: 2001 | C12: 311.97932
A13: AUT | B13: 2002 | C13: 386.63779
A14: AUT | B14: 2003 | C14: 478.8744
... A507: SWE | B507: 2023 | C507: 15456.19

Sheet policy_name_clustering
A1: full name | B1: dominant instrument | C1: cluster name
A2: FiT | B2: FiT | C2: FiT/FiP-based
A3: FiT prolonged, FiT support duration increased | B3: FiT | C3: FiT/FiP-based
A4: FiP | B4: FiP | C4: FiT/FiP-based
A5: Tender | B5: Tender | C5: Tender-based
A6: Tender, FiP, Loan guarantee | B6: FiP | C6: Policy mix
A7: Tax incentive increase, TGC aim increase, Tender | B7: Tender | C7: Policy mix
A8: TGC | B8: TGC | C8: TGC-based
A9: Tax incentive | B9: Tax incentive | C9: Tax-based
A10: Tax incentive, TGC | B10: TGC | C10: Policy mix
A11: Subsidy prolonged | B11: Subsidy | C11: Other single instrument
A12: Tax incentive, Subsidy, TGC | B12: TGC | C12: Policy mix
... A16: Tax incentive extended, Tender | B16: Tender | C16: Policy mix
